Workbook

Sheet LISTADOS TFM
B2: LISTADOS TFM / TFG | O2: V.02
V3: Cerrado
C4: TÍTULO: Máster U. en Bioinformática | V4: Abierto con comentario
C5: EDICIÓN: Octubre 25 | K5: CURSO: 25-26 | V5: Cerrado con comentario
V7: SECRETARÍA
A8: NOMBRE COMPLETO | B8: DNI | C8: E-MAIL DEL ALUMNO | D8: DIRECTOR/A TFT APELLIDO APELLIDO, NOMBRE | E8: DIRECTOR TFT APELLIDOS | F8: DIRECTOR TFT NOMBRE | G8: CORREO DIRECTOR/A | H8: TEMA TFT | I8: TÍTULO TFM / TFG | J8: Presidente/a | K8: Secretario/a | L8: Vocal | M8: FECHA DE DEFENSA | N8: HORA | O8: CALIFICACION FINAL | P8: ORIENTACIÓN | Q8: PERIODO LECTURA | R8: GRUPO | S8: TUTORIZADO SÍ/ NO | T8: Nº CREDITOS | U8: COMENTARIOS | V8: ESTADO ACTA | W8: COMENTARIO ACTA | X8: GRUPAL | Y8: Nº GRUPO
A9: Chaparro Santos, Paula Alejandra | B9: AU284013 | C9: paulachaparro65@gmail.com | D9: Vallalta Rueda, Juan Francisco | E9: =IFERROR(VLOOKUP(G9,'DATOS ASIGNACIÓN'!B:I,7,0),"") | F9: =IFERROR(VLOOKUP(G9,'DATOS ASIGNACIÓN'!B:I,6,0),"") | G9: juanfrancisco.vallalta@professor.universidadviu.com | H9: Programación Python | R9: Z
A10: Díaz Alberola, Irene | B10: 53740292X | C10: idiazalberola@gmail.com | D10: Vallalta Rueda, Juan Francisco | E10: =IFERROR(VLOOKUP(G10,'DATOS ASIGNACIÓN'!B:I,7,0),"") | F10: =IFERROR(VLOOKUP(G10,'DATOS ASIGNACIÓN'!B:I,6,0),"") | G10: juanfrancisco.vallalta@professor.universidadviu.com | H10: Programación Python | R10: Z
A11: Gutiérrez Morocho, Álvaro | B11: 12425951V | C11: omorochalvaro@gmail.com | D11: Torres Moral, Teresa | E11: =IFERROR(VLOOKUP(G11,'DATOS ASIGNACIÓN'!B:I,7,0),"") | F11: =IFERROR(VLOOKUP(G11,'DATOS ASIGNACIÓN'!B:I,6,0),"") | G11: ttorresmo@uoc.edu | H11: Metagenómica | R11: Z
A12: Lozano Zacarías, Ulises José | B12: 48763198R | C12: uliseslozano7@gmail.com | D12: Lairón Peris, Maria | E12: =IFERROR(VLOOKUP(G12,'DATOS ASIGNACIÓN'!B:I,7,0),"") | F12: =IFERROR(VLOOKUP(G12,'DATOS ASIGNACIÓN'!B:I,6,0),"") | G12: maria.lairon@professor.universidadviu.com | H12: Metataxonómica | R12: Z
A13: Machancoses Hernández, Francisco Miguel | B13: 03937142W | C13: fmachancosesh@gmail.com | D13: Díaz Vidal, Tania | E13: =IFERROR(VLOOKUP(G13,'DATOS ASIGNACIÓN'!B:I,7,0),"") | F13: =IFERROR(VLOOKUP(G13,'DATOS ASIGNACIÓN'!B:I,6,0),"") | G13: tdiazv@professor.universidadviu.com | H13: Proteómica Estructural | R13: Z
A14: Miranda González, Alejandro | B14: 03951203X | C14: ale.miranda3733@gmail.com | D14: Fraga Seijas, Carlota | E14: =IFERROR(VLOOKUP(G14,'DATOS ASIGNACIÓN'!B:I,7,0),"") | F14: =IFERROR(VLOOKUP(G14,'DATOS ASIGNACIÓN'!B:I,6,0),"") | G14: cfragas@professional.universidadviu.com | H14: Transcriptómica | R14: Z
A15: Santos Santana, Eliana Yurany | B15: 1018447296 | C15: elianasantoss23@gmail.com | D15: Lairón Peris, Maria | E15: =IFERROR(VLOOKUP(G15,'DATOS ASIGNACIÓN'!B:I,7,0),"") | F15: =IFERROR(VLOOKUP(G15,'DATOS ASIGNACIÓN'!B:I,6,0),"") | G15: maria.lairon@professor.universidadviu.com | H15: Secuenciación genómica | R15: Z
A16: Sende Pombo, Martín | B16: 45959869G | C16: msendepombo@student.universidadviu.com | D16: Sendra Ortola, Miquel | E16: =IFERROR(VLOOKUP(G16,'DATOS ASIGNACIÓN'!B:I,7,0),"") | F16: =IFERROR(VLOOKUP(G16,'DATOS ASIGNACIÓN'!B:I,6,0),"") | G16: miquel.sendra@professor.universidadviu.com | H16: Transcriptómica | R16: Z
A17: Torres Marcos, Inés | B17: 77043656G | C17: itorresm01@gmail.com | D17: Del Saz Navarro, Dulcenombre de María | E17: =IFERROR(VLOOKUP(G17,'DATOS ASIGNACIÓN'!B:I,7,0),"") | F17: =IFERROR(VLOOKUP(G17,'DATOS ASIGNACIÓN'!B:I,6,0),"") | G17: ddelsazn@professor.universidadviu.com | H17: Programación Python | R17: Z
A18: Agudin Monte, Laura | B18: 71738612W | C18: lagudinm@student.universidadviu.com | D18: Martínez Montañés, Fernando
A19: Ahmed Ahmed, Anisa | B19: 45313101L | C19: aahmeda@student.universidadviu.com | D19: Hernández Hernández, Laura
A20: Alcala Zamora Polo, Jose | B20: 32906862A | C20: jalcalazamorap@student.universidadviu.com | D20: Tobar Tosse, Henry Fabian
A21: Alemán Cabrera, Isabel María | B21: 45343421W | C21: ialemanc@student.universidadviu.com | D21: Castiñeira Reis, Marta
A22: Almazán Díaz, Laura | B22: 53664285H | C22: lalmazand@student.universidadviu.com | D22: Bigay Mercedes, Bary Georderly
A23: Alvarez Jiménez, Johana Sthefany | B23: 73431974N | C23: jalvarezjimenez@student.universidadviu.com | D23: Marín García, Pablo
A24: Andino Gualpa, Liseth Verónica | B24: A8405298 | C24: landinog@student.universidadviu.com | D24: Rubio Mangas, David
A25: Arroyo Carmona, Aurora | B25: 24496220R | C25: aarroyocarmona@student.universidadviu.com | D25: Vázquez Prieto, Severo
A26: Bahraoui Badouch, Chaimae | B26: 78770027H | C26: cbahraouib@student.universidadviu.com | D26: Castiñeira Reis, Marta
A27: Benítez López, Alicia | B27: 32904275S | C27: abenitezl@student.universidadviu.com | D27: Sendra Ortola, Miquel
A28: Berbel Menacho, Julia | B28: 17484262F | C28: jberbelm@student.universidadviu.com | D28: García Atutxa, Igor
A29: Blanco Martínez, Enol | B29: 53678224L | C29: eblancomartinez@student.universidadviu.com | D29: Guijarro Blanco, José María
A30: Brondegaard García, David | D30: Del Saz Navarro, Dulcenombre de María
A31: Burns, Millicent Grace | B31: Y0069791T | C31: mburns@student.universidadviu.com | D31: Hernández Hernández, Laura
A32: Bustamante De La Escalera, Pedro | B32: 72207420R | C32: pbustamanted@student.universidadviu.com | D32: Guijarro Blanco, José María
A33: Calero Cáceres, William Ricardo | B33: 1714348859 | C33: wcaleroc@student.universidadviu.com | D33: Valiente Parra, Nicolás
A34: Calomarde Garcia, Juan | B34: 49433155Z | C34: jcalomardeg@student.universidadviu.com | D34: Morante Palacios, Octavio
A35: Canello, Alejo | B35: 42769884 | C35: acanello@student.universidadviu.com | D35: Hernández Hernández, Laura
A36: Cardona Ferrer, Ivan | B36: 20236883B | C36: icardonaferrer@student.universidadviu.com | D36: Moldovan Moldovan, Roxana Andreea
A37: Carrillo Alarcon, Pedro | B37: 26827256X | C37: pcarrilloalarcon@student.universidadviu.com | D37: Martínez Montañés, Fernando
A38: Carrillo Garcia, Laia | B38: 48197417C | C38: lcarrillogarcia@student.universidadviu.com | D38: Bonzi, Carolina
A39: Carrion Padilla, Javier | B39: 77864244K | C39: jcarrionpadilla@student.universidadviu.com | D39: Hernández Hernández, Laura
A40: Carvalho Gil, Juan Alfredo | B40: 07177643X | C40: jcarvalhog@student.universidadviu.com | D40: Bonzi, Carolina
A41: Casero Muñoz, Luis | B41: 77860002B | C41: lcaseromunozm@student.universidadviu.com | D41: Morante Palacios, Octavio
A42: Cañizares Villalba, Sebastian Alejandro | B42: 927754945 | C42: scanizaresvillalba@student.universidadviu.com | D42: Neef, Alexander
...

Sheet DATOS ASIGNACIÓN
B4: Apellido Apellido, Nombre | C4: Número de TFT para asignar | D4: Número de TFT Asignados | E4: DNI | F4: VINCULACIÓN | G4: NOMBRE | H4: APELLIDOS | I4: CORREO | T4: Tribunal
B5: {=_xlfn.UNIQUE(S5:S1300)} | S5: =IF('[1]REGISTRO ECTS TFT'!$J10>0,'[1]REGISTRO ECTS TFT'!$B10,"") | T5: ='[2]DATOS DOCENTES'!$D4 -> Abad Villaverde, Beatriz
B6: Castiñeira Reis, Marta | C6: =VLOOKUP(B6,'[1]REGISTRO ECTS TFT'!$B:$AD,9,0) -> 3 | D6: =COUNTIF('LISTADOS TFM'!D$9:D$502,'DATOS ASIGNACIÓN'!B6) -> 3 | E6: =VLOOKUP(B6,'[2]DATOS DOCENTES'!$D:$AI,32,0) -> 35579937H | F6: =VLOOKUP(E6,'[2]DATOS DOCENTES'!$A:$M,13,0) -> Labour | G6: =VLOOKUP(E6,'[2]DATOS DOCENTES'!$A:$F,3,0) -> Marta | H6: =VLOOKUP(E6,'[2]DATOS DOCENTES'!$A:$F,2,0) -> Castiñeira Reis | I6: =VLOOKUP(E6,'[2]DATOS DOCENTES'!$A:$F,6,0) -> mcastineirasr@professor.universidadviu.com | S6: =IF('[1]REGISTRO ECTS TFT'!$J11>0,'[1]REGISTRO ECTS TFT'!$B11,"") | T6: ='[2]DATOS DOCENTES'!$D5 -> Abalo Rodríguez, Inés
B7: Del Saz Navarro, Dulcenombre de María | C7: =VLOOKUP(B7,'[1]REGISTRO ECTS TFT'!$B:$AD,9,0) -> 10 | D7: =COUNTIF('LISTADOS TFM'!D$9:D$502,'DATOS ASIGNACIÓN'!B7) -> 9 | E7: =VLOOKUP(B7,'[2]DATOS DOCENTES'!$D:$AI,32,0) -> 53344676V | F7: =VLOOKUP(E7,'[2]DATOS DOCENTES'!$A:$M,13,0) -> Labour | G7: =VLOOKUP(E7,'[2]DATOS DOCENTES'!$A:$F,3,0) -> Dulcenombre de María | H7: =VLOOKUP(E7,'[2]DATOS DOCENTES'!$A:$F,2,0) -> Del Saz Navarro | I7: =VLOOKUP(E7,'[2]DATOS DOCENTES'!$A:$F,6,0) -> ddelsazn@professor.universidadviu.com | S7: =IF('[1]REGISTRO ECTS TFT'!$J12>0,'[1]REGISTRO ECTS TFT'!$B12,"") | T7: ='[2]DATOS DOCENTES'!$D6 -> Abarca Sos, Alberto
B8: Díaz Vidal, Tania | C8: =VLOOKUP(B8,'[1]REGISTRO ECTS TFT'!$B:$AD,9,0) -> 3 | D8: =COUNTIF('LISTADOS TFM'!D$9:D$502,'DATOS ASIGNACIÓN'!B8) -> 3 | E8: =VLOOKUP(B8,'[2]DATOS DOCENTES'!$D:$AI,32,0) -> 47772101C | F8: =VLOOKUP(E8,'[2]DATOS DOCENTES'!$A:$M,13,0) -> Labour | G8: =VLOOKUP(E8,'[2]DATOS DOCENTES'!$A:$F,3,0) -> Tania | H8: =VLOOKUP(E8,'[2]DATOS DOCENTES'!$A:$F,2,0) -> Díaz Vidal | I8: =VLOOKUP(E8,'[2]DATOS DOCENTES'!$A:$F,6,0) -> tdiazv@professor.universidadviu.com | S8: =IF('[1]REGISTRO ECTS TFT'!$J13>0,'[1]REGISTRO ECTS TFT'!$B13,"") | T8: ='[2]DATOS DOCENTES'!$D7 -> Abarca Torralba, Mari Carmen
B9: Gutiérrez Macías, Laura | C9: =VLOOKUP(B9,'[1]REGISTRO ECTS TFT'!$B:$AD,9,0) -> 2 | D9: =COUNTIF('LISTADOS TFM'!D$9:D$502,'DATOS ASIGNACIÓN'!B9) -> 2 | E9: =VLOOKUP(B9,'[2]DATOS DOCENTES'!$D:$AI,32,0) -> 71451984T | F9: =VLOOKUP(E9,'[2]DATOS DOCENTES'!$A:$M,13,0) -> Labour | G9: =VLOOKUP(E9,'[2]DATOS DOCENTES'!$A:$F,3,0) -> Laura | H9: =VLOOKUP(E9,'[2]DATOS DOCENTES'!$A:$F,2,0) -> Gutiérrez Macías | I9: =VLOOKUP(E9,'[2]DATOS DOCENTES'!$A:$F,6,0) -> laura.gutierrez.m@professor.universidadviu.com | S9: =IF('[1]REGISTRO ECTS TFT'!$J14>0,'[1]REGISTRO ECTS TFT'!$B14,"") | T9: ='[2]DATOS DOCENTES'!$D8 -> Abellán Sánchez, María del Rosario
B10: Lairón Peris, Maria | C10: =VLOOKUP(B10,'[1]REGISTRO ECTS TFT'!$B:$AD,9,0) -> 2 | D10: =COUNTIF('LISTADOS TFM'!D$9:D$502,'DATOS ASIGNACIÓN'!B10) -> 2 | E10: =VLOOKUP(B10,'[2]DATOS DOCENTES'!$D:$AI,32,0) -> 20858109F | F10: =VLOOKUP(E10,'[2]DATOS DOCENTES'!$A:$M,13,0) -> Labour | G10: =VLOOKUP(E10,'[2]DATOS DOCENTES'!$A:$F,3,0) -> Maria | H10: =VLOOKUP(E10,'[2]DATOS DOCENTES'!$A:$F,2,0) -> Lairón Peris | I10: =VLOOKUP(E10,'[2]DATOS DOCENTES'!$A:$F,6,0) -> maria.lairon@professor.universidadviu.com | S10: =IF('[1]REGISTRO ECTS TFT'!$J15>0,'[1]REGISTRO ECTS TFT'!$B15,"") | T10: ='[2]DATOS DOCENTES'!$D9 -> Abia Holgado, David Ángel
B11: Pedrero Tomé, Roberto | C11: =VLOOKUP(B11,'[1]REGISTRO ECTS TFT'!$B:$AD,9,0) -> 4 | D11: =COUNTIF('LISTADOS TFM'!D$9:D$502,'DATOS ASIGNACIÓN'!B11) -> 0 | E11: =VLOOKUP(B11,'[2]DATOS DOCENTES'!$D:$AI,32,0) -> 53804408W | F11: =VLOOKUP(E11,'[2]DATOS DOCENTES'!$A:$M,13,0) -> Labour | G11: =VLOOKUP(E11,'[2]DATOS DOCENTES'!$A:$F,3,0) -> Roberto | H11: =VLOOKUP(E11,'[2]DATOS DOCENTES'!$A:$F,2,0) -> Pedrero Tomé | I11: =VLOOKUP(E11,'[2]DATOS DOCENTES'!$A:$F,6,0) -> rpedrerot@professor.universidadviu.com | S11: =IF('[1]REGISTRO ECTS TFT'!$J16>0,'[1]REGISTRO ECTS TFT'!$B16,"") | T11: ='[2]DATOS DOCENTES'!$D10 -> Acebes Andreu, Félix
B12: Rubio Mangas, David | C12: =VLOOKUP(B12,'[1]REGISTRO ECTS TFT'!$B:$AD,9,0) -> 4 | D12: =COUNTIF('LISTADOS TFM'!D$9:D$502,'DATOS ASIGNACIÓN'!B12) -> 4 | E12: =VLOOKUP(B12,'[2]DATOS DOCENTES'!$D:$AI,32,0) -> 53477696M | F12: =VLOOKUP(E12,'[2]DATOS DOCENTES'!$A:$M,13,0) -> Labour | G12: =VLOOKUP(E12,'[2]DATOS DOCENTES'!$A:$F,3,0) -> David | H12: =VLOOKUP(E12,'[2]DATOS DOCENTES'!$A:$F,2,0) -> Rubio Mangas | I12: =VLOOKUP(E12,'[2]DATOS DOCENTES'!$A:$F,6,0) -> drubiom@professor.universidadviu.com | S12: =IF('[1]REGISTRO ECTS TFT'!$J17>0,'[1]REGISTRO ECTS TFT'!$B17,"") | T12: ='[2]DATOS DOCENTES'!$D11 -> Acebes Sánchez, Jorge
B13: Sendra Ortola, Miquel | C13: =VLOOKUP(B13,'[1]REGISTRO ECTS TFT'!$B:$AD,9,0) -> 6 | D13: =COUNTIF('LISTADOS TFM'!D$9:D$502,'DATOS ASIGNACIÓN'!B13) -> 6 | E13: =VLOOKUP(B13,'[2]DATOS DOCENTES'!$D:$AI,32,0) -> 48671191V | F13: =VLOOKUP(E13,'[2]DATOS DOCENTES'!$A:$M,13,0) -> Labour | G13: =VLOOKUP(E13,'[2]DATOS DOCENTES'!$A:$F,3,0) -> Miquel | H13: =VLOOKUP(E13,'[2]DATOS DOCENTES'!$A:$F,2,0) -> Sendra Ortola | I13: =VLOOKUP(E13,'[2]DATOS DOCENTES'!$A:$F,6,0) -> miquel.sendra@professor.universidadviu.com | S13: =IF('[1]REGISTRO ECTS TFT'!$J18>0,'[1]REGISTRO ECTS TFT'!$B18,"") | T13: ='[2]DATOS DOCENTES'!$D12 -> Aceituno Solís, Javier
B14: Soler Vila, Paula | C14: =VLOOKUP(B14,'[1]REGISTRO ECTS TFT'!$B:$AD,9,0) -> 4 | D14: =COUNTIF('LISTADOS TFM'!D$9:D$502,'DATOS ASIGNACIÓN'!B14) -> 0 | E14: =VLOOKUP(B14,'[2]DATOS DOCENTES'!$D:$AI,32,0) -> 48294021R | F14: =VLOOKUP(E14,'[2]DATOS DOCENTES'!$A:$M,13,0) -> Labour | G14: =VLOOKUP(E14,'[2]DATOS DOCENTES'!$A:$F,3,0) -> Paula | H14: =VLOOKUP(E14,'[2]DATOS DOCENTES'!$A:$F,2,0) -> Soler Vila | I14: =VLOOKUP(E14,'[2]DATOS DOCENTES'!$A:$F,6,0) -> paula.solerv@professor.universidadviu.com | S14: =IF('[1]REGISTRO ECTS TFT'!$J19>0,'[1]REGISTRO ECTS TFT'!$B19,"") | T14: ='[2]DATOS DOCENTES'!$D13 -> Acha Durán, María Nieves
B15: Torres Moral, Teresa | C15: =VLOOKUP(B15,'[1]REGISTRO ECTS TFT'!$B:$AD,9,0) -> 4 | D15: =COUNTIF('LISTADOS TFM'!D$9:D$502,'DATOS ASIGNACIÓN'!B15) -> 4 | E15: =VLOOKUP(B15,'[2]DATOS DOCENTES'!$D:$AI,32,0) -> 47926664T | F15: =VLOOKUP(E15,'[2]DATOS DOCENTES'!$A:$M,13,0) -> Labour | G15: =VLOOKUP(E15,'[2]DATOS DOCENTES'!$A:$F,3,0) -> Teresa | H15: =VLOOKUP(E15,'[2]DATOS DOCENTES'!$A:$F,2,0) -> Torres Moral | I15: =VLOOKUP(E15,'[2]DATOS DOCENTES'!$A:$F,6,0) -> ttorresm@professor.universidadviu.com | S15: =IF('[1]REGISTRO ECTS TFT'!$J20>0,'[1]REGISTRO ECTS TFT'!$B20,"") | T15: ='[2]DATOS DOCENTES'!$D14 -> Acosta González, Paola
B16: Vallalta Rueda, Juan Francisco | C16: =VLOOKUP(B16,'[1]REGISTRO ECTS TFT'!$B:$AD,9,0) -> 2 | D16: =COUNTIF('LISTADOS TFM'!D$9:D$502,'DATOS ASIGNACIÓN'!B16) -> 2 | E16: =VLOOKUP(B16,'[2]DATOS DOCENTES'!$D:$AI,32,0) -> 25126556E | F16: =VLOOKUP(E16,'[2]DATOS DOCENTES'!$A:$M,13,0) -> Labour | G16: =VLOOKUP(E16,'[2]DATOS DOCENTES'!$A:$F,3,0) -> Juan Francisco | H16: =VLOOKUP(E16,'[2]DATOS DOCENTES'!$A:$F,2,0) -> Vallalta Rueda | I16: =VLOOKUP(E16,'[2]DATOS DOCENTES'!$A:$F,6,0) -> juanfrancisco.vallalta@professor.universidadviu.com | S16: =IF('[1]REGISTRO ECTS TFT'!$J21>0,'[1]REGISTRO ECTS TFT'!$B21,"") | T16: ='[2]DATOS DOCENTES'!$D15 -> Acosta Herrera, Marialbert
B17: Bigay Mercedes, Bary Georderly | C17: =VLOOKUP(B17,'[1]REGISTRO ECTS TFT'!$B:$AD,9,0) -> 9 | D17: =COUNTIF('LISTADOS TFM'!D$9:D$502,'DATOS ASIGNACIÓN'!B17) -> 9 | E17: =VLOOKUP(B17,'[2]DATOS DOCENTES'!$D:$AI,32,0) -> 40213993831 | F17: =VLOOKUP(E17,'[2]DATOS DOCENTES'!$A:$M,13,0) -> Professional | G17: =VLOOKUP(E17,'[2]DATOS DOCENTES'!$A:$F,3,0) -> Bary Georderly | H17: =VLOOKUP(E17,'[2]DATOS DOCENTES'!$A:$F,2,0) -> Bigay Mercedes | I17: =VLOOKUP(E17,'[2]DATOS DOCENTES'!$A:$F,6,0) -> bbigaym@professional.universidadviu.com | S17: =IF('[1]REGISTRO ECTS TFT'!$J22>0,'[1]REGISTRO ECTS TFT'!$B22,"") | T17: ='[2]DATOS DOCENTES'!$D16 -> Acosta Pérez, Irene
... B37: Zúñiga Trejos, Sheila | C37: =VLOOKUP(B37,'[1]REGISTRO ECTS TFT'!$B:$AD,9,0) -> 2 | D37: =COUNTIF('LISTADOS TFM'!D$9:D$502,'DATOS ASIGNACIÓN'!B37) -> 2 | E37: =VLOOKUP(B37,'[2]DATOS DOCENTES'!$D:$AI,32,0) -> 70874038K | F37: =VLOOKUP(E37,'[2]DATOS DOCENTES'!$A:$M,13,0) -> Professional | G37: =VLOOKUP(E37,'[2]DATOS DOCENTES'!$A:$F,3,0) -> Sheila | H37: =VLOOKUP(E37,'[2]DATOS DOCENTES'!$A:$F,2,0) -> Zúñiga Trejos | I37: =VLOOKUP(E37,'[2]DATOS DOCENTES'!$A:$F,6,0) -> sheila.zuniga@professional.universidadviu.com | S37: =IF('[1]REGISTRO ECTS TFT'!$J42>0,'[1]REGISTRO ECTS TFT'!$B42,"") | T37: ='[2]DATOS DOCENTES'!$D36 -> Aliño Costa, Marta
C38: =VLOOKUP(B38,'[1]REGISTRO ECTS TFT'!$B:$AD,9,0) -> #N/A | D38: =COUNTIF('LISTADOS TFM'!D$9:D$502,'DATOS ASIGNACIÓN'!B38) -> 0 | E38: =VLOOKUP(B38,'[2]DATOS DOCENTES'!$D:$AI,32,0) -> #N/A | F38: =VLOOKUP(E38,'[2]DATOS DOCENTES'!$A:$M,13,0) -> #N/A | G38: =VLOOKUP(E38,'[2]DATOS DOCENTES'!$A:$F,3,0) -> #N/A | H38: =VLOOKUP(E38,'[2]DATOS DOCENTES'!$A:$F,2,0) -> #N/A | I38: =VLOOKUP(E38,'[2]DATOS DOCENTES'!$A:$F,6,0) -> #N/A | S38: =IF('[1]REGISTRO ECTS TFT'!$J43>0,'[1]REGISTRO ECTS TFT'!$B43,"") | T38: ='[2]DATOS DOCENTES'!$D37 -> Almaraz Morocho, David
C39: =VLOOKUP(B39,'[1]REGISTRO ECTS TFT'!$B:$AD,9,0) -> #N/A | D39: =COUNTIF('LISTADOS TFM'!D$9:D$502,'DATOS ASIGNACIÓN'!B39) -> 0 | E39: =VLOOKUP(B39,'[2]DATOS DOCENTES'!$D:$AI,32,0) -> #N/A | F39: =VLOOKUP(E39,'[2]DATOS DOCENTES'!$A:$M,13,0) -> #N/A | G39: =VLOOKUP(E39,'[2]DATOS DOCENTES'!$A:$F,3,0) -> #N/A | H39: =VLOOKUP(E39,'[2]DATOS DOCENTES'!$A:$F,2,0) -> #N/A | I39: =VLOOKUP(E39,'[2]DATOS DOCENTES'!$A:$F,6,0) -> #N/A | S39: =IF('[1]REGISTRO ECTS TFT'!$J44>0,'[1]REGISTRO ECTS TFT'!$B44,"") | T39: ='[2]DATOS DOCENTES'!$D38 -> Almeida Toledano, Laura
C40: =VLOOKUP(B40,'[1]REGISTRO ECTS TFT'!$B:$AD,9,0) -> #N/A | D40: =COUNTIF('LISTADOS TFM'!D$9:D$502,'DATOS ASIGNACIÓN'!B40) -> 0 | E40: =VLOOKUP(B40,'[2]DATOS DOCENTES'!$D:$AI,32,0) -> #N/A | F40: =VLOOKUP(E40,'[2]DATOS DOCENTES'!$A:$M,13,0) -> #N/A | G40: =VLOOKUP(E40,'[2]DATOS DOCENTES'!$A:$F,3,0) -> #N/A | H40: =VLOOKUP(E40,'[2]DATOS DOCENTES'!$A:$F,2,0) -> #N/A | I40: =VLOOKUP(E40,'[2]DATOS DOCENTES'!$A:$F,6,0) -> #N/A | S40: =IF('[1]REGISTRO ECTS TFT'!$J45>0,'[1]REGISTRO ECTS TFT'!$B45,"") | T40: ='[2]DATOS DOCENTES'!$D39 -> Alonso del Real Arias, Javier
C41: =VLOOKUP(B41,'[1]REGISTRO ECTS TFT'!$B:$AD,9,0) -> #N/A | D41: =COUNTIF('LISTADOS TFM'!D$9:D$502,'DATOS ASIGNACIÓN'!B41) -> 0 | E41: =VLOOKUP(B41,'[2]DATOS DOCENTES'!$D:$AI,32,0) -> #N/A | F41: =VLOOKUP(E41,'[2]DATOS DOCENTES'!$A:$M,13,0) -> #N/A | G41: =VLOOKUP(E41,'[2]DATOS DOCENTES'!$A:$F,3,0) -> #N/A | H41: =VLOOKUP(E41,'[2]DATOS DOCENTES'!$A:$F,2,0) -> #N/A | I41: =VLOOKUP(E41,'[2]DATOS DOCENTES'!$A:$F,6,0) -> #N/A | S41: =IF('[1]REGISTRO ECTS TFT'!$J46>0,'[1]REGISTRO ECTS TFT'!$B46,"") | T41: ='[2]DATOS DOCENTES'!$D40 -> Alonso Guillén, María Sandra
C42: =VLOOKUP(B42,'[1]REGISTRO ECTS TFT'!$B:$AD,9,0) -> #N/A | D42: =COUNTIF('LISTADOS TFM'!D$9:D$502,'DATOS ASIGNACIÓN'!B42) -> 0 | E42: =VLOOKUP(B42,'[2]DATOS DOCENTES'!$D:$AI,32,0) -> #N/A | F42: =VLOOKUP(E42,'[2]DATOS DOCENTES'!$A:$M,13,0) -> #N/A | G42: =VLOOKUP(E42,'[2]DATOS DOCENTES'!$A:$F,3,0) -> #N/A | H42: =VLOOKUP(E42,'[2]DATOS DOCENTES'!$A:$F,2,0) -> #N/A | I42: =VLOOKUP(E42,'[2]DATOS DOCENTES'!$A:$F,6,0) -> #N/A | S42: =IF('[1]REGISTRO ECTS TFT'!$J47>0,'[1]REGISTRO ECTS TFT'!$B47,"") | T42: ='[2]DATOS DOCENTES'!$D41 -> Alonso Riera, María Ángeles
C43: =VLOOKUP(B43,'[1]REGISTRO ECTS TFT'!$B:$AD,9,0) -> #N/A | D43: =COUNTIF('LISTADOS TFM'!D$9:D$502,'DATOS ASIGNACIÓN'!B43) -> 0 | E43: =VLOOKUP(B43,'[2]DATOS DOCENTES'!$D:$AI,32,0) -> #N/A | F43: =VLOOKUP(E43,'[2]DATOS DOCENTES'!$A:$M,13,0) -> #N/A | G43: =VLOOKUP(E43,'[2]DATOS DOCENTES'!$A:$F,3,0) -> #N/A | H43: =VLOOKUP(E43,'[2]DATOS DOCENTES'!$A:$F,2,0) -> #N/A | I43: =VLOOKUP(E43,'[2]DATOS DOCENTES'!$A:$F,6,0) -> #N/A | S43: =IF('[1]REGISTRO ECTS TFT'!$J48>0,'[1]REGISTRO ECTS TFT'!$B48,"") | T43: ='[2]DATOS DOCENTES'!$D42 -> Alonso Sanz, Ángel María
C44: =VLOOKUP(B44,'[1]REGISTRO ECTS TFT'!$B:$AD,9,0) -> #N/A | D44: =COUNTIF('LISTADOS TFM'!D$9:D$502,'DATOS ASIGNACIÓN'!B44) -> 0 | E44: =VLOOKUP(B44,'[2]DATOS DOCENTES'!$D:$AI,32,0) -> #N/A | F44: =VLOOKUP(E44,'[2]DATOS DOCENTES'!$A:$M,13,0) -> #N/A | G44: =VLOOKUP(E44,'[2]DATOS DOCENTES'!$A:$F,3,0) -> #N/A | H44: =VLOOKUP(E44,'[2]DATOS DOCENTES'!$A:$F,2,0) -> #N/A | I44: =VLOOKUP(E44,'[2]DATOS DOCENTES'!$A:$F,6,0) -> #N/A | S44: =IF('[1]REGISTRO ECTS TFT'!$J49>0,'[1]REGISTRO ECTS TFT'!$B49,"") | T44: ='[2]DATOS DOCENTES'!$D43 -> Alonso Vaquerizo, Irene
C45: =VLOOKUP(B45,'[1]REGISTRO ECTS TFT'!$B:$AD,9,0) -> #N/A | D45: =COUNTIF('LISTADOS TFM'!D$9:D$502,'DATOS ASIGNACIÓN'!B45) -> 0 | E45: =VLOOKUP(B45,'[2]DATOS DOCENTES'!$D:$AI,32,0) -> #N/A | F45: =VLOOKUP(E45,'[2]DATOS DOCENTES'!$A:$M,13,0) -> #N/A | G45: =VLOOKUP(E45,'[2]DATOS DOCENTES'!$A:$F,3,0) -> #N/A | H45: =VLOOKUP(E45,'[2]DATOS DOCENTES'!$A:$F,2,0) -> #N/A | I45: =VLOOKUP(E45,'[2]DATOS DOCENTES'!$A:$F,6,0) -> #N/A | S45: =IF('[1]REGISTRO ECTS TFT'!$J50>0,'[1]REGISTRO ECTS TFT'!$B50,"") -> Gutiérrez Macías, Laura | T45: ='[2]DATOS DOCENTES'!$D44 -> Alvarado Muñoz-Quiros, Ayla María
C46: =VLOOKUP(B46,'[1]REGISTRO ECTS TFT'!$B:$AD,9,0) -> #N/A | D46: =COUNTIF('LISTADOS TFM'!D$9:D$502,'DATOS ASIGNACIÓN'!B46) -> 0 | E46: =VLOOKUP(B46,'[2]DATOS DOCENTES'!$D:$AI,32,0) -> #N/A | F46: =VLOOKUP(E46,'[2]DATOS DOCENTES'!$A:$M,13,0) -> #N/A | G46: =VLOOKUP(E46,'[2]DATOS DOCENTES'!$A:$F,3,0) -> #N/A | H46: =VLOOKUP(E46,'[2]DATOS DOCENTES'!$A:$F,2,0) -> #N/A | I46: =VLOOKUP(E46,'[2]DATOS DOCENTES'!$A:$F,6,0) -> #N/A | S46: =IF('[1]REGISTRO ECTS TFT'!$J51>0,'[1]REGISTRO ECTS TFT'!$B51,"") | T46: ='[2]DATOS DOCENTES'!$D45 -> Alvarenga Capurró, Claudia Beatriz
C47: =VLOOKUP(B47,'[1]REGISTRO ECTS TFT'!$B:$AD,9,0) -> #N/A | D47: =COUNTIF('LISTADOS TFM'!D$9:D$502,'DATOS ASIGNACIÓN'!B47) -> 0 | E47: =VLOOKUP(B47,'[2]DATOS DOCENTES'!$D:$AI,32,0) -> #N/A | F47: =VLOOKUP(E47,'[2]DATOS DOCENTES'!$A:$M,13,0) -> #N/A | G47: =VLOOKUP(E47,'[2]DATOS DOCENTES'!$A:$F,3,0) -> #N/A | H47: =VLOOKUP(E47,'[2]DATOS DOCENTES'!$A:$F,2,0) -> #N/A | I47: =VLOOKUP(E47,'[2]DATOS DOCENTES'!$A:$F,6,0) -> #N/A | S47: =IF('[1]REGISTRO ECTS TFT'!$J52>0,'[1]REGISTRO ECTS TFT'!$B52,"") | T47: ='[2]DATOS DOCENTES'!$D46 -> Álvarez de Toledo Blandon, María de la Paloma
C48: =VLOOKUP(B48,'[1]REGISTRO ECTS TFT'!$B:$AD,9,0) -> #N/A | D48: =COUNTIF('LISTADOS TFM'!D$9:D$502,'DATOS ASIGNACIÓN'!B48) -> 0 | E48: =VLOOKUP(B48,'[2]DATOS DOCENTES'!$D:$AI,32,0) -> #N/A | F48: =VLOOKUP(E48,'[2]DATOS DOCENTES'!$A:$M,13,0) -> #N/A | G48: =VLOOKUP(E48,'[2]DATOS DOCENTES'!$A:$F,3,0) -> #N/A | H48: =VLOOKUP(E48,'[2]DATOS DOCENTES'!$A:$F,2,0) -> #N/A | I48: =VLOOKUP(E48,'[2]DATOS DOCENTES'!$A:$F,6,0) -> #N/A | S48: =IF('[1]REGISTRO ECTS TFT'!$J53>0,'[1]REGISTRO ECTS TFT'!$B53,"") | T48: ='[2]DATOS DOCENTES'!$D47 -> Álvarez Ferradas, Carla
C49: =VLOOKUP(B49,'[1]REGISTRO ECTS TFT'!$B:$AD,9,0) -> #N/A | D49: =COUNTIF('LISTADOS TFM'!D$9:D$502,'DATOS ASIGNACIÓN'!B49) -> 0 | E49: =VLOOKUP(B49,'[2]DATOS DOCENTES'!$D:$AI,32,0) -> #N/A | F49: =VLOOKUP(E49,'[2]DATOS DOCENTES'!$A:$M,13,0) -> #N/A | G49: =VLOOKUP(E49,'[2]DATOS DOCENTES'!$A:$F,3,0) -> #N/A | H49: =VLOOKUP(E49,'[2]DATOS DOCENTES'!$A:$F,2,0) -> #N/A | I49: =VLOOKUP(E49,'[2]DATOS DOCENTES'!$A:$F,6,0) -> #N/A | S49: =IF('[1]REGISTRO ECTS TFT'!$J54>0,'[1]REGISTRO ECTS TFT'!$B54,"") | T49: ='[2]DATOS DOCENTES'!$D48 -> Álvarez Monsalve, Elisa
... C54: =VLOOKUP(B54,'[1]REGISTRO ECTS TFT'!$B:$AD,9,0) -> #N/A | D54: =COUNTIF('LISTADOS TFM'!D$9:D$502,'DATOS ASIGNACIÓN'!B54) -> 0 | E54: =VLOOKUP(B54,'[2]DATOS DOCENTES'!$D:$AI,32,0) -> #N/A | F54: =VLOOKUP(E54,'[2]DATOS DOCENTES'!$A:$M,13,0) -> #N/A | G54: =VLOOKUP(E54,'[2]DATOS DOCENTES'!$A:$F,3,0) -> #N/A | H54: =VLOOKUP(E54,'[2]DATOS DOCENTES'!$A:$F,2,0) -> #N/A | I54: =VLOOKUP(E54,'[2]DATOS DOCENTES'!$A:$F,6,0) -> #N/A | S54: =IF('[1]REGISTRO ECTS TFT'!$J59>0,'[1]REGISTRO ECTS TFT'!$B59,"") | T54: ='[2]DATOS DOCENTES'!$D53 -> Amor González, Antonio Manuel
C55: =VLOOKUP(B55,'[1]REGISTRO ECTS TFT'!$B:$AD,9,0) -> #N/A | D55: =COUNTIF('LISTADOS TFM'!D$153:D$502,'DATOS ASIGNACIÓN'!B55) -> 0 | F55: =VLOOKUP(E55,'[2]DATOS DOCENTES'!$A:$M,13,0) -> #N/A | S55: =IF('[1]REGISTRO ECTS TFT'!$J60>0,'[1]REGISTRO ECTS TFT'!$B60,"") | T55: ='[2]DATOS DOCENTES'!$D54 -> Amores Marreiros, Rubén
C56: =VLOOKUP(B56,'[1]REGISTRO ECTS TFT'!$B:$AD,9,0) -> #N/A | D56: =COUNTIF('LISTADOS TFM'!D$153:D$502,'DATOS ASIGNACIÓN'!B56) -> 0 | F56: =VLOOKUP(E56,'[2]DATOS DOCENTES'!$A:$M,13,0) -> #N/A | S56: =IF('[1]REGISTRO ECTS TFT'!$J61>0,'[1]REGISTRO ECTS TFT'!$B61,"") | T56: ='[2]DATOS DOCENTES'!$D55 -> Andrés Blasco, Irene
C57: =VLOOKUP(B57,'[1]REGISTRO ECTS TFT'!$B:$AD,9,0) -> #N/A | D57: =COUNTIF('LISTADOS TFM'!D$153:D$502,'DATOS ASIGNACIÓN'!B57) -> 0 | F57: =VLOOKUP(E57,'[2]DATOS DOCENTES'!$A:$M,13,0) -> #N/A | S57: =IF('[1]REGISTRO ECTS TFT'!$J62>0,'[1]REGISTRO ECTS TFT'!$B62,"") | T57: ='[2]DATOS DOCENTES'!$D56 -> Andreu Fernández, Vicente
C58: =VLOOKUP(B58,'[1]REGISTRO ECTS TFT'!$B:$AD,9,0) -> #N/A | D58: =COUNTIF('LISTADOS TFM'!D$153:D$502,'DATOS ASIGNACIÓN'!B58) -> 0 | F58: =VLOOKUP(E58,'[2]DATOS DOCENTES'!$A:$M,13,0) -> #N/A | S58: =IF('[1]REGISTRO ECTS TFT'!$J63>0,'[1]REGISTRO ECTS TFT'!$B63,"") | T58: ='[2]DATOS DOCENTES'!$D57 -> Antón Blasco, José Antonio
C59: =VLOOKUP(B59,'[1]REGISTRO ECTS TFT'!$B:$AD,9,0) -> #N/A | D59: =COUNTIF('LISTADOS TFM'!D$153:D$502,'DATOS ASIGNACIÓN'!B59) -> 0 | F59: =VLOOKUP(E59,'[2]DATOS DOCENTES'!$A:$M,13,0) -> #N/A | S59: =IF('[1]REGISTRO ECTS TFT'!$J64>0,'[1]REGISTRO ECTS TFT'!$B64,"") | T59: ='[2]DATOS DOCENTES'!$D58 -> Antón Riquelme, Ana Asunción
C60: =VLOOKUP(B60,'[1]REGISTRO ECTS TFT'!$B:$AD,9,0) -> #N/A | D60: =COUNTIF('LISTADOS TFM'!D$153:D$502,'DATOS ASIGNACIÓN'!B60) -> 0 | F60: =VLOOKUP(E60,'[2]DATOS DOCENTES'!$A:$M,13,0) -> #N/A | S60: =IF('[1]REGISTRO ECTS TFT'!$J65>0,'[1]REGISTRO ECTS TFT'!$B65,"") | T60: ='[2]DATOS DOCENTES'!$D59 -> Antón Santiago, Roberto
C61: =VLOOKUP(B61,'[1]REGISTRO ECTS TFT'!$B:$AD,9,0) -> #N/A | D61: =COUNTIF('LISTADOS TFM'!D$153:D$502,'DATOS ASIGNACIÓN'!B61) -> 0 | F61: =VLOOKUP(E61,'[2]DATOS DOCENTES'!$A:$M,13,0) -> #N/A | S61: =IF('[1]REGISTRO ECTS TFT'!$J66>0,'[1]REGISTRO ECTS TFT'!$B66,"") | T61: ='[2]DATOS DOCENTES'!$D60 -> Aracil Bolaños, Ignacio
C62: =VLOOKUP(B62,'[1]REGISTRO ECTS TFT'!$B:$AD,9,0) -> #N/A | D62: =COUNTIF('LISTADOS TFM'!D$153:D$502,'DATOS ASIGNACIÓN'!B62) -> 0 | F62: =VLOOKUP(E62,'[2]DATOS DOCENTES'!$A:$M,13,0) -> #N/A | S62: =IF('[1]REGISTRO ECTS TFT'!$J67>0,'[1]REGISTRO ECTS TFT'!$B67,"") | T62: ='[2]DATOS DOCENTES'!$D61 -> Araos Gómez, Pedro Fernando
C63: =VLOOKUP(B63,'[1]REGISTRO ECTS TFT'!$B:$AD,9,0) -> #N/A | D63: =COUNTIF('LISTADOS TFM'!D$153:D$502,'DATOS ASIGNACIÓN'!B63) -> 0 | F63: =VLOOKUP(E63,'[2]DATOS DOCENTES'!$A:$M,13,0) -> #N/A | S63: =IF('[1]REGISTRO ECTS TFT'!$J68>0,'[1]REGISTRO ECTS TFT'!$B68,"") | T63: ='[2]DATOS DOCENTES'!$D62 -> Aras López, Rosa María
C64: =VLOOKUP(B64,'[1]REGISTRO ECTS TFT'!$B:$AD,9,0) -> #N/A | D64: =COUNTIF('LISTADOS TFM'!D$153:D$502,'DATOS ASIGNACIÓN'!B64) -> 0 | F64: =VLOOKUP(E64,'[2]DATOS DOCENTES'!$A:$M,13,0) -> #N/A | S64: =IF('[1]REGISTRO ECTS TFT'!$J69>0,'[1]REGISTRO ECTS TFT'!$B69,"") | T64: ='[2]DATOS DOCENTES'!$D63 -> Arce Recatalá, Cristina
C65: =VLOOKUP(B65,'[1]REGISTRO ECTS TFT'!$B:$AD,9,0) -> #N/A | D65: =COUNTIF('LISTADOS TFM'!D$153:D$502,'DATOS ASIGNACIÓN'!B65) -> 0 | F65: =VLOOKUP(E65,'[2]DATOS DOCENTES'!$A:$M,13,0) -> #N/A | S65: =IF('[1]REGISTRO ECTS TFT'!$J70>0,'[1]REGISTRO ECTS TFT'!$B70,"") | T65: ='[2]DATOS DOCENTES'!$D64 -> Argudo Palacios, Aarón
C66: =VLOOKUP(B66,'[1]REGISTRO ECTS TFT'!$B:$AD,9,0) -> #N/A | D66: =COUNTIF('LISTADOS TFM'!D$153:D$502,'DATOS ASIGNACIÓN'!B66) -> 0 | F66: =VLOOKUP(E66,'[2]DATOS DOCENTES'!$A:$M,13,0) -> #N/A | S66: =IF('[1]REGISTRO ECTS TFT'!$J71>0,'[1]REGISTRO ECTS TFT'!$B71,"") | T66: ='[2]DATOS DOCENTES'!$D65 -> Argyropulou, Vasiliki
...

Sheet Hoja 2
A1: Apellido Apellido, Nombre | B1: Apellidos | C1: Nombre | D1: NIF
A2: Abad Villaverde, Beatriz | B2: Abad Villaverde | C2: Beatriz | D2: 76941444G
A3: =IFERROR(__xludf.UNSUPPORTED("""COMPUTED_VALUE"""),"Abarca Sos, Alberto") -> Abarca Sos, Alberto | B3: =IFERROR(__xludf.UNSUPPORTED("""COMPUTED_VALUE"""),"Abarca Sos") -> Abarca Sos | C3: =IFERROR(__xludf.UNSUPPORTED("""COMPUTED_VALUE"""),"Alberto") -> Alberto | D3: =IFERROR(__xludf.UNSUPPORTED("""COMPUTED_VALUE"""),"25191300K") -> 25191300K
A4: =IFERROR(__xludf.UNSUPPORTED("""COMPUTED_VALUE"""),"Abarca Torralba, Mari Carmen") -> Abarca Torralba, Mari Carmen | B4: =IFERROR(__xludf.UNSUPPORTED("""COMPUTED_VALUE"""),"Abarca Torralba") -> Abarca Torralba | C4: =IFERROR(__xludf.UNSUPPORTED("""COMPUTED_VALUE"""),"Mari Carmen") -> Mari Carmen | D4: =IFERROR(__xludf.UNSUPPORTED("""COMPUTED_VALUE"""),"25412227X") -> 25412227X
A5: =IFERROR(__xludf.UNSUPPORTED("""COMPUTED_VALUE"""),"Abellán Sánchez, María del Rosario") -> Abellán Sánchez, María del Rosario | B5: =IFERROR(__xludf.UNSUPPORTED("""COMPUTED_VALUE"""),"Abellán Sánchez") -> Abellán Sánchez | C5: =IFERROR(__xludf.UNSUPPORTED("""COMPUTED_VALUE"""),"María del Rosario") -> María del Rosario | D5: =IFERROR(__xludf.UNSUPPORTED("""COMPUTED_VALUE"""),"46615013Q") -> 46615013Q
A6: =IFERROR(__xludf.UNSUPPORTED("""COMPUTED_VALUE"""),"Acebes Sánchez, Jorge") -> Acebes Sánchez, Jorge | B6: =IFERROR(__xludf.UNSUPPORTED("""COMPUTED_VALUE"""),"Acebes Sánchez") -> Acebes Sánchez | C6: =IFERROR(__xludf.UNSUPPORTED("""COMPUTED_VALUE"""),"Jorge") -> Jorge | D6: =IFERROR(__xludf.UNSUPPORTED("""COMPUTED_VALUE"""),"08933309V") -> 08933309V
A7: =IFERROR(__xludf.UNSUPPORTED("""COMPUTED_VALUE"""),"Acosta Pérez, Irene") -> Acosta Pérez, Irene | B7: =IFERROR(__xludf.UNSUPPORTED("""COMPUTED_VALUE"""),"Acosta Pérez") -> Acosta Pérez | C7: =IFERROR(__xludf.UNSUPPORTED("""COMPUTED_VALUE"""),"Irene") -> Irene | D7: =IFERROR(__xludf.UNSUPPORTED("""COMPUTED_VALUE"""),"54113650D") -> 54113650D
A8: =IFERROR(__xludf.UNSUPPORTED("""COMPUTED_VALUE"""),"Acosta Pumarejo, Enrique") -> Acosta Pumarejo, Enrique | B8: =IFERROR(__xludf.UNSUPPORTED("""COMPUTED_VALUE"""),"Acosta Pumarejo") -> Acosta Pumarejo | C8: =IFERROR(__xludf.UNSUPPORTED("""COMPUTED_VALUE"""),"Enrique") -> Enrique | D8: =IFERROR(__xludf.UNSUPPORTED("""COMPUTED_VALUE"""),"09898018Z") -> 09898018Z
A9: =IFERROR(__xludf.UNSUPPORTED("""COMPUTED_VALUE"""),"Adam Artigues, Anna") -> Adam Artigues, Anna | B9: =IFERROR(__xludf.UNSUPPORTED("""COMPUTED_VALUE"""),"Adam Artigues") -> Adam Artigues | C9: =IFERROR(__xludf.UNSUPPORTED("""COMPUTED_VALUE"""),"Anna") -> Anna | D9: =IFERROR(__xludf.UNSUPPORTED("""COMPUTED_VALUE"""),"53626940W") -> 53626940W
A10: =IFERROR(__xludf.UNSUPPORTED("""COMPUTED_VALUE"""),"Aguayo Romero, Virginia") -> Aguayo Romero, Virginia | B10: =IFERROR(__xludf.UNSUPPORTED("""COMPUTED_VALUE"""),"Aguayo Romero") -> Aguayo Romero | C10: =IFERROR(__xludf.UNSUPPORTED("""COMPUTED_VALUE"""),"Virginia") -> Virginia | D10: =IFERROR(__xludf.UNSUPPORTED("""COMPUTED_VALUE"""),"05712817P") -> 05712817P
A11: =IFERROR(__xludf.UNSUPPORTED("""COMPUTED_VALUE"""),"Aguilera Martínez, Penélope") -> Aguilera Martínez, Penélope | B11: =IFERROR(__xludf.UNSUPPORTED("""COMPUTED_VALUE"""),"Aguilera Martínez") -> Aguilera Martínez | C11: =IFERROR(__xludf.UNSUPPORTED("""COMPUTED_VALUE"""),"Penélope") -> Penélope | D11: =IFERROR(__xludf.UNSUPPORTED("""COMPUTED_VALUE"""),"78978032B") -> 78978032B
A12: =IFERROR(__xludf.UNSUPPORTED("""COMPUTED_VALUE"""),"Agustí López, Ana Isabel") -> Agustí López, Ana Isabel | B12: =IFERROR(__xludf.UNSUPPORTED("""COMPUTED_VALUE"""),"Agustí López") -> Agustí López | C12: =IFERROR(__xludf.UNSUPPORTED("""COMPUTED_VALUE"""),"Ana Isabel") -> Ana Isabel | D12: =IFERROR(__xludf.UNSUPPORTED("""COMPUTED_VALUE"""),"20457022V") -> 20457022V
A13: =IFERROR(__xludf.UNSUPPORTED("""COMPUTED_VALUE"""),"Alabadí Pardiñes, Blanca") -> Alabadí Pardiñes, Blanca | B13: =IFERROR(__xludf.UNSUPPORTED("""COMPUTED_VALUE"""),"Alabadí Pardiñes") -> Alabadí Pardiñes | C13: =IFERROR(__xludf.UNSUPPORTED("""COMPUTED_VALUE"""),"Blanca") -> Blanca | D13: =IFERROR(__xludf.UNSUPPORTED("""COMPUTED_VALUE"""),"45911043F") -> 45911043F
A14: =IFERROR(__xludf.UNSUPPORTED("""COMPUTED_VALUE"""),"Alaminos Hervás, María Dolores") -> Alaminos Hervás, María Dolores | B14: =IFERROR(__xludf.UNSUPPORTED("""COMPUTED_VALUE"""),"Alaminos Hervás") -> Alaminos Hervás | C14: =IFERROR(__xludf.UNSUPPORTED("""COMPUTED_VALUE"""),"María Dolores") -> María Dolores | D14: =IFERROR(__xludf.UNSUPPORTED("""COMPUTED_VALUE"""),"02896070W") -> 02896070W
A15: =IFERROR(__xludf.UNSUPPORTED("""COMPUTED_VALUE"""),"Alarco Rosales, Raquel") -> Alarco Rosales, Raquel | B15: =IFERROR(__xludf.UNSUPPORTED("""COMPUTED_VALUE"""),"Alarco Rosales") -> Alarco Rosales | C15: =IFERROR(__xludf.UNSUPPORTED("""COMPUTED_VALUE"""),"Raquel") -> Raquel | D15: =IFERROR(__xludf.UNSUPPORTED("""COMPUTED_VALUE"""),"44879197X") -> 44879197X
A16: =IFERROR(__xludf.UNSUPPORTED("""COMPUTED_VALUE"""),"Alba Muñoz, Julen") -> Alba Muñoz, Julen | B16: =IFERROR(__xludf.UNSUPPORTED("""COMPUTED_VALUE"""),"Alba Muñoz") -> Alba Muñoz | C16: =IFERROR(__xludf.UNSUPPORTED("""COMPUTED_VALUE"""),"Julen") -> Julen | D16: =IFERROR(__xludf.UNSUPPORTED("""COMPUTED_VALUE"""),"16071571E") -> 16071571E
A17: =IFERROR(__xludf.UNSUPPORTED("""COMPUTED_VALUE"""),"Albaladejo Perales, Rosa María") -> Albaladejo Perales, Rosa María | B17: =IFERROR(__xludf.UNSUPPORTED("""COMPUTED_VALUE"""),"Albaladejo Perales") -> Albaladejo Perales | C17: =IFERROR(__xludf.UNSUPPORTED("""COMPUTED_VALUE"""),"Rosa María") -> Rosa María | D17: =IFERROR(__xludf.UNSUPPORTED("""COMPUTED_VALUE"""),"45568697Q") -> 45568697Q
A18: =IFERROR(__xludf.UNSUPPORTED("""COMPUTED_VALUE"""),"Alberola Enguix, Salvador") -> Alberola Enguix, Salvador | B18: =IFERROR(__xludf.UNSUPPORTED("""COMPUTED_VALUE"""),"Alberola Enguix") -> Alberola Enguix | C18: =IFERROR(__xludf.UNSUPPORTED("""COMPUTED_VALUE"""),"Salvador") -> Salvador | D18: =IFERROR(__xludf.UNSUPPORTED("""COMPUTED_VALUE"""),"20035516D") -> 20035516D
A19: =IFERROR(__xludf.UNSUPPORTED("""COMPUTED_VALUE"""),"Alconada Padilla, Roberto") -> Alconada Padilla, Roberto | B19: =IFERROR(__xludf.UNSUPPORTED("""COMPUTED_VALUE"""),"Alconada Padilla") -> Alconada Padilla | C19: =IFERROR(__xludf.UNSUPPORTED("""COMPUTED_VALUE"""),"Roberto") -> Roberto | D19: =IFERROR(__xludf.UNSUPPORTED("""COMPUTED_VALUE"""),"20060747D") -> 20060747D
A20: =IFERROR(__xludf.UNSUPPORTED("""COMPUTED_VALUE"""),"Alhambra Borrás, Tamara") -> Alhambra Borrás, Tamara | B20: =IFERROR(__xludf.UNSUPPORTED("""COMPUTED_VALUE"""),"Alhambra Borrás") -> Alhambra Borrás | C20: =IFERROR(__xludf.UNSUPPORTED("""COMPUTED_VALUE"""),"Tamara") -> Tamara | D20: =IFERROR(__xludf.UNSUPPORTED("""COMPUTED_VALUE"""),"45798873P") -> 45798873P
A21: =IFERROR(__xludf.UNSUPPORTED("""COMPUTED_VALUE"""),"Aliño Costa, Marta") -> Aliño Costa, Marta | B21: =IFERROR(__xludf.UNSUPPORTED("""COMPUTED_VALUE"""),"Aliño Costa") -> Aliño Costa | C21: =IFERROR(__xludf.UNSUPPORTED("""COMPUTED_VALUE"""),"Marta") -> Marta | D21: =IFERROR(__xludf.UNSUPPORTED("""COMPUTED_VALUE"""),"20847305J") -> 20847305J
A22: =IFERROR(__xludf.UNSUPPORTED("""COMPUTED_VALUE"""),"Almaraz Morocho, David") -> Almaraz Morocho, David | B22: =IFERROR(__xludf.UNSUPPORTED("""COMPUTED_VALUE"""),"Almaraz Morocho") -> Almaraz Morocho | C22: =IFERROR(__xludf.UNSUPPORTED("""COMPUTED_VALUE"""),"David") -> David | D22: =IFERROR(__xludf.UNSUPPORTED("""COMPUTED_VALUE"""),"70902210H") -> 70902210H
A23: =IFERROR(__xludf.UNSUPPORTED("""COMPUTED_VALUE"""),"Almeida Toledano, Laura") -> Almeida Toledano, Laura | B23: =IFERROR(__xludf.UNSUPPORTED("""COMPUTED_VALUE"""),"Almeida Toledano") -> Almeida Toledano | C23: =IFERROR(__xludf.UNSUPPORTED("""COMPUTED_VALUE"""),"Laura") -> Laura | D23: =IFERROR(__xludf.UNSUPPORTED("""COMPUTED_VALUE"""),"53073953G") -> 53073953G
A24: =IFERROR(__xludf.UNSUPPORTED("""COMPUTED_VALUE"""),"Alonso del Real Arias, Javier") -> Alonso del Real Arias, Javier | B24: =IFERROR(__xludf.UNSUPPORTED("""COMPUTED_VALUE"""),"Alonso del Real Arias") -> Alonso del Real Arias | C24: =IFERROR(__xludf.UNSUPPORTED("""COMPUTED_VALUE"""),"Javier") -> Javier | D24: =IFERROR(__xludf.UNSUPPORTED("""COMPUTED_VALUE"""),"53353764C") -> 53353764C
A25: =IFERROR(__xludf.UNSUPPORTED("""COMPUTED_VALUE"""),"Alonso Riera, María Ángeles") -> Alonso Riera, María Ángeles | B25: =IFERROR(__xludf.UNSUPPORTED("""COMPUTED_VALUE"""),"Alonso Riera") -> Alonso Riera | C25: =IFERROR(__xludf.UNSUPPORTED("""COMPUTED_VALUE"""),"María Ángeles") -> María Ángeles | D25: =IFERROR(__xludf.UNSUPPORTED("""COMPUTED_VALUE"""),"02094621B") -> 02094621B
A26: =IFERROR(__xludf.UNSUPPORTED("""COMPUTED_VALUE"""),"Alvarado Muñoz-Quiros, Ayla María") -> Alvarado Muñoz-Quiros, Ayla María | B26: =IFERROR(__xludf.UNSUPPORTED("""COMPUTED_VALUE"""),"Alvarado Muñoz-Quiros") -> Alvarado Muñoz-Quiros | C26: =IFERROR(__xludf.UNSUPPORTED("""COMPUTED_VALUE"""),"Ayla María") -> Ayla María | D26: =IFERROR(__xludf.UNSUPPORTED("""COMPUTED_VALUE"""),"74368051N") -> 74368051N
A27: =IFERROR(__xludf.UNSUPPORTED("""COMPUTED_VALUE"""),"Alvarenga Capurró, Claudia Beatriz") -> Alvarenga Capurró, Claudia Beatriz | B27: =IFERROR(__xludf.UNSUPPORTED("""COMPUTED_VALUE"""),"Alvarenga Capurró") -> Alvarenga Capurró | C27: =IFERROR(__xludf.UNSUPPORTED("""COMPUTED_VALUE"""),"Claudia Beatriz") -> Claudia Beatriz | D27: =IFERROR(__xludf.UNSUPPORTED("""COMPUTED_VALUE"""),"47279592X") -> 47279592X
A28: =IFERROR(__xludf.UNSUPPORTED("""COMPUTED_VALUE"""),"Álvarez de Toledo Blandon, María de la Paloma") -> Álvarez de Toledo Blandon, María de la Paloma | B28: =IFERROR(__xludf.UNSUPPORTED("""COMPUTED_VALUE"""),"Álvarez de Toledo Blandon") -> Álvarez de Toledo Blandon | C28: =IFERROR(__xludf.UNSUPPORTED("""COMPUTED_VALUE"""),"María de la Paloma") -> María de la Paloma | D28: =IFERROR(__xludf.UNSUPPORTED("""COMPUTED_VALUE"""),"77800448G") -> 77800448G
A29: =IFERROR(__xludf.UNSUPPORTED("""COMPUTED_VALUE"""),"Álvarez Monsalve, Elisa") -> Álvarez Monsalve, Elisa | B29: =IFERROR(__xludf.UNSUPPORTED("""COMPUTED_VALUE"""),"Álvarez Monsalve") -> Álvarez Monsalve | C29: =IFERROR(__xludf.UNSUPPORTED("""COMPUTED_VALUE"""),"Elisa") -> Elisa | D29: =IFERROR(__xludf.UNSUPPORTED("""COMPUTED_VALUE"""),63476582) -> 63476582
A30: =IFERROR(__xludf.UNSUPPORTED("""COMPUTED_VALUE"""),"Amaoui, Sofia") -> Amaoui, Sofia | B30: =IFERROR(__xludf.UNSUPPORTED("""COMPUTED_VALUE"""),"Amaoui") -> Amaoui | C30: =IFERROR(__xludf.UNSUPPORTED("""COMPUTED_VALUE"""),"Sofia") -> Sofia | D30: =IFERROR(__xludf.UNSUPPORTED("""COMPUTED_VALUE"""),"Y2589177N") -> Y2589177N
A31: =IFERROR(__xludf.UNSUPPORTED("""COMPUTED_VALUE"""),"Amezcua Valmala, Nerea") -> Amezcua Valmala, Nerea | B31: =IFERROR(__xludf.UNSUPPORTED("""COMPUTED_VALUE"""),"Amezcua Valmala") -> Amezcua Valmala | C31: =IFERROR(__xludf.UNSUPPORTED("""COMPUTED_VALUE"""),"Nerea") -> Nerea | D31: =IFERROR(__xludf.UNSUPPORTED("""COMPUTED_VALUE"""),"72742464L") -> 72742464L
A32: =IFERROR(__xludf.UNSUPPORTED("""COMPUTED_VALUE"""),"Amor González, Antonio Manuel") -> Amor González, Antonio Manuel | B32: =IFERROR(__xludf.UNSUPPORTED("""COMPUTED_VALUE"""),"Amor González") -> Amor González | C32: =IFERROR(__xludf.UNSUPPORTED("""COMPUTED_VALUE"""),"Antonio Manuel") -> Antonio Manuel | D32: =IFERROR(__xludf.UNSUPPORTED("""COMPUTED_VALUE"""),"53579329R") -> 53579329R
A33: =IFERROR(__xludf.UNSUPPORTED("""COMPUTED_VALUE"""),"Andrés Blasco, Irene") -> Andrés Blasco, Irene | B33: =IFERROR(__xludf.UNSUPPORTED("""COMPUTED_VALUE"""),"Andrés Blasco") -> Andrés Blasco | C33: =IFERROR(__xludf.UNSUPPORTED("""COMPUTED_VALUE"""),"Irene") -> Irene | D33: =IFERROR(__xludf.UNSUPPORTED("""COMPUTED_VALUE"""),"18448878A") -> 18448878A
A34: =IFERROR(__xludf.UNSUPPORTED("""COMPUTED_VALUE"""),"Andreu Fernández, Vicente") -> Andreu Fernández, Vicente | B34: =IFERROR(__xludf.UNSUPPORTED("""COMPUTED_VALUE"""),"Andreu Fernández") -> Andreu Fernández | C34: =IFERROR(__xludf.UNSUPPORTED("""COMPUTED_VALUE"""),"Vicente") -> Vicente | D34: =IFERROR(__xludf.UNSUPPORTED("""COMPUTED_VALUE"""),"48503496S") -> 48503496S
A35: =IFERROR(__xludf.UNSUPPORTED("""COMPUTED_VALUE"""),"Antón Santiago, Roberto") -> Antón Santiago, Roberto | B35: =IFERROR(__xludf.UNSUPPORTED("""COMPUTED_VALUE"""),"Antón Santiago") -> Antón Santiago | C35: =IFERROR(__xludf.UNSUPPORTED("""COMPUTED_VALUE"""),"Roberto") -> Roberto | D35: =IFERROR(__xludf.UNSUPPORTED("""COMPUTED_VALUE"""),"52498719T") -> 52498719T
A36: =IFERROR(__xludf.UNSUPPORTED("""COMPUTED_VALUE"""),"Aras López, Rosa María") -> Aras López, Rosa María | B36: =IFERROR(__xludf.UNSUPPORTED("""COMPUTED_VALUE"""),"Aras López") -> Aras López | C36: =IFERROR(__xludf.UNSUPPORTED("""COMPUTED_VALUE"""),"Rosa María") -> Rosa María | D36: =IFERROR(__xludf.UNSUPPORTED("""COMPUTED_VALUE"""),"01934823V") -> 01934823V
A37: =IFERROR(__xludf.UNSUPPORTED("""COMPUTED_VALUE"""),"Arce Recatalá, Cristina") -> Arce Recatalá, Cristina | B37: =IFERROR(__xludf.UNSUPPORTED("""COMPUTED_VALUE"""),"Arce Recatalá") -> Arce Recatalá | C37: =IFERROR(__xludf.UNSUPPORTED("""COMPUTED_VALUE"""),"Cristina") -> Cristina | D37: =IFERROR(__xludf.UNSUPPORTED("""COMPUTED_VALUE"""),"29208833Y") -> 29208833Y
A38: =IFERROR(__xludf.UNSUPPORTED("""COMPUTED_VALUE"""),"Argudo Palacios, Aarón") -> Argudo Palacios, Aarón | B38: =IFERROR(__xludf.UNSUPPORTED("""COMPUTED_VALUE"""),"Argudo Palacios") -> Argudo Palacios | C38: =IFERROR(__xludf.UNSUPPORTED("""COMPUTED_VALUE"""),"Aarón") -> Aarón | D38: =IFERROR(__xludf.UNSUPPORTED("""COMPUTED_VALUE"""),"39384262M") -> 39384262M
A39: =IFERROR(__xludf.UNSUPPORTED("""COMPUTED_VALUE"""),"Argyropulou, Vasiliki") -> Argyropulou, Vasiliki | B39: =IFERROR(__xludf.UNSUPPORTED("""COMPUTED_VALUE"""),"Argyropulou") -> Argyropulou | C39: =IFERROR(__xludf.UNSUPPORTED("""COMPUTED_VALUE"""),"Vasiliki") -> Vasiliki | D39: =IFERROR(__xludf.UNSUPPORTED("""COMPUTED_VALUE"""),"Y5811436V") -> Y5811436V
A40: =IFERROR(__xludf.UNSUPPORTED("""COMPUTED_VALUE"""),"Arias de la Cruz, Sonia") -> Arias de la Cruz, Sonia | B40: =IFERROR(__xludf.UNSUPPORTED("""COMPUTED_VALUE"""),"Arias de la Cruz") -> Arias de la Cruz | C40: =IFERROR(__xludf.UNSUPPORTED("""COMPUTED_VALUE"""),"Sonia") -> Sonia | D40: =IFERROR(__xludf.UNSUPPORTED("""COMPUTED_VALUE"""),"49018430W") -> 49018430W
...

Sheet Pagos
B16: DIRECCION | D16: < 9 | E16: 160 | G16: TRIBUNAL | H16: 20
D17: 12 | E17: 200 | G17: CRÉDITOS PROFESIONALES.: | H17: 0
D18: 15-18 | E18: 200 | G18: CRÉDITOS INVESTIGADORA.: | H18: 0
B20: Mercantil | C20: NIF Colaborador | D20: Num. tutorizaciones | E20: Num. tribunales | G20: €€ Tutorizaciones | H20: €€ Num.Tribunales | I20: PAGO ÍNTEGRO (cumplimentar "SÍ" si no han realizado todos los tribunales siguiendo la regla 1x3 pero hay que pasar el pago íntegro) | K20: IMPORTE TOTAL A ABONAR | L20: COMENTARIOS | M20: Nº Tutorizaciones (1) | N20: nº Tribunales (1) | O20: €€ Tutorizaciones (1) | P20: €€ Num.Tribunales (1) | Q20: IMPORTE TOTAL A ABONAR | R20: Pasado a VR (SÍ/NO) | S20: Nº Tutorizaciones (2) | T20: nº Tribunales (2) | U20: €€ Tutorizaciones (2) | V20: €€ Num.Tribunales (2) | W20: IMPORTE TOTAL A ABONAR | X20: Pasado a VR (SÍ/NO) | Y20: Nº Tutorizaciones (3) | Z20: nº Tribunales (3) | AA20: €€ Tutorizaciones (3) | AB20: €€ Num.Tribunales (3) | AC20: IMPORTE TOTAL A ABONAR | AD20: Pasado a VR (SÍ/NO) | AE20: Nº Tutorizaciones (4) | AF20: nº Tribunales (4) | AG20: €€ Tutorizaciones (4) | AH20: €€ Num.Tribunales (4) | AI20: IMPORTE TOTAL A ABONAR | AJ20: Pasado a VR (SÍ/NO)
A21: PROFESIONAL | B21: Bigay Mercedes, Bary Georderly | C21: =VLOOKUP(B21,'DATOS ASIGNACIÓN'!B:I,4,0) -> 40213993831 | D21: =COUNTIFS('LISTADOS TFM'!D:D,Pagos!B21,'LISTADOS TFM'!S:S,"SÍ") -> 0 | E21: =COUNTIF('LISTADOS TFM'!J:L,Pagos!B21) -> 0 | G21: =IF($H$17<9,$E$16,IF($H$17=$D$17,$E$17,$E$18))*D21 -> 0 | H21: =+E21*$H$16 -> 0 | J21: =IF(I21="SÍ",H21*-1,0) -> 0 | K21: =+G21+H21 -> 0 | M21: =+D21 -> 0 | N21: =+E21 -> 0 | O21: =IF($H$17<9,$E$16,IF($H$17=$D$17,$E$17,$E$18))*M21 -> 0 | P21: =+N21*$H$16 -> 0 | Q21: =+O21+P21 -> 0 | S21: =+D21-M21 -> 0 | T21: =+E21-N21 -> 0 | U21: =IF($H$17<9,$E$16,IF($H$17=$D$17,$E$17,$E$18))*S21 -> 0 | V21: =+T21*$H$16 -> 0 | W21: =+U21+V21 -> 0 | Y21: =+D21-M21-S21 -> 0 | Z21: =+E21-N21-T21 -> 0 | AA21: =IF($H$17<9,$E$16,IF($H$17=$D$17,$E$17,$E$18))*Y21 -> 0 | AB21: =+Z21*$H$16 -> 0 | AC21: =+AA21+AB21 -> 0 | AE21: =+D21-M21-S21-Y21 -> 0 | AF21: =+E21-N21-T21-Z21 -> 0 | AG21: =IF($H$17<9,$E$16,IF($H$17=$D$17,$E$17,$E$18))*AE21 -> 0 | AH21: =+AF21*$H$16 -> 0 | AI21: =+AG21+AH21 -> 0
A22: PROFESIONAL | B22: Bonzi, Carolina | C22: =VLOOKUP(B22,'DATOS ASIGNACIÓN'!B:I,4,0) -> ECBNZCLN81D64L219F | D22: =COUNTIFS('LISTADOS TFM'!D:D,Pagos!B22,'LISTADOS TFM'!S:S,"SÍ") -> 0 | E22: =COUNTIF('LISTADOS TFM'!J:L,Pagos!B22) -> 0 | F22: =IF(D22*3=E22,"OK",IF(D22*3<E22,"EXTRA","VALORAR")) -> OK | G22: =IF($H$17<9,$E$16,IF($H$17=$D$17,$E$17,$E$18))*D22 -> 0 | H22: =+E22*$H$16 -> 0 | J22: =IF(I22="SÍ",H22*-1,0) -> 0 | K22: =+G22+H22 -> 0 | M22: =+D22 -> 0 | N22: =+E22 -> 0 | O22: =IF($H$17<9,$E$16,IF($H$17=$D$17,$E$17,$E$18))*M22 -> 0 | P22: =+N22*$H$16 -> 0 | Q22: =+O22+P22 -> 0 | S22: =+D22-M22 -> 0 | T22: =+E22-N22 -> 0 | U22: =IF($H$17<9,$E$16,IF($H$17=$D$17,$E$17,$E$18))*S22 -> 0 | V22: =+T22*$H$16 -> 0 | W22: =+U22+V22 -> 0 | Y22: =+D22-M22-S22 -> 0 | Z22: =+E22-N22-T22 -> 0 | AA22: =IF($H$17<9,$E$16,IF($H$17=$D$17,$E$17,$E$18))*Y22 -> 0 | AB22: =+Z22*$H$16 -> 0 | AC22: =+AA22+AB22 -> 0 | AE22: =+D22-M22-S22-Y22 -> 0 | AF22: =+E22-N22-T22-Z22 -> 0 | AG22: =IF($H$17<9,$E$16,IF($H$17=$D$17,$E$17,$E$18))*AE22 -> 0 | AH22: =+AF22*$H$16 -> 0 | AI22: =+AG22+AH22 -> 0
A23: PROFESIONAL | B23: Cartas Cejudo, Paz | C23: =VLOOKUP(B23,'DATOS ASIGNACIÓN'!B:I,4,0) -> 26500888N | D23: =COUNTIFS('LISTADOS TFM'!D:D,Pagos!B23,'LISTADOS TFM'!S:S,"SÍ") -> 0 | E23: =COUNTIF('LISTADOS TFM'!J:L,Pagos!B23) -> 0 | G23: =IF($H$17<9,$E$16,IF($H$17=$D$17,$E$17,$E$18))*D23 -> 0 | H23: =+E23*$H$16 -> 0 | J23: =IF(I23="SÍ",H23*-1,0) -> 0 | K23: =+G23+H23 -> 0 | M23: =+D23 -> 0 | N23: =+E23 -> 0 | O23: =IF($H$17<9,$E$16,IF($H$17=$D$17,$E$17,$E$18))*M23 -> 0 | P23: =+N23*$H$16 -> 0 | Q23: =+O23+P23 -> 0 | S23: =+D23-M23 -> 0 | T23: =+E23-N23 -> 0 | U23: =IF($H$17<9,$E$16,IF($H$17=$D$17,$E$17,$E$18))*S23 -> 0 | V23: =+T23*$H$16 -> 0 | W23: =+U23+V23 -> 0 | Y23: =+D23-M23-S23 -> 0 | Z23: =+E23-N23-T23 -> 0 | AA23: =IF($H$17<9,$E$16,IF($H$17=$D$17,$E$17,$E$18))*Y23 -> 0 | AB23: =+Z23*$H$16 -> 0 | AC23: =+AA23+AB23 -> 0 | AE23: =+D23-M23-S23-Y23 -> 0 | AF23: =+E23-N23-T23-Z23 -> 0 | AG23: =IF($H$17<9,$E$16,IF($H$17=$D$17,$E$17,$E$18))*AE23 -> 0 | AH23: =+AF23*$H$16 -> 0 | AI23: =+AG23+AH23 -> 0
A24: PROFESIONAL | B24: Fraga Seijas, Carlota | C24: =VLOOKUP(B24,'DATOS ASIGNACIÓN'!B:I,4,0) -> 47361323E | D24: =COUNTIFS('LISTADOS TFM'!D:D,Pagos!B24,'LISTADOS TFM'!S:S,"SÍ") -> 0 | E24: =COUNTIF('LISTADOS TFM'!J:L,Pagos!B24) -> 0 | G24: =IF($H$17<9,$E$16,IF($H$17=$D$17,$E$17,$E$18))*D24 -> 0 | H24: =+E24*$H$16 -> 0 | J24: =IF(I24="SÍ",H24*-1,0) -> 0 | K24: =+G24+H24 -> 0 | M24: =+D24 -> 0 | N24: =+E24 -> 0 | O24: =IF($H$17<9,$E$16,IF($H$17=$D$17,$E$17,$E$18))*M24 -> 0 | P24: =+N24*$H$16 -> 0 | Q24: =+O24+P24 -> 0 | S24: =+D24-M24 -> 0 | T24: =+E24-N24 -> 0 | U24: =IF($H$17<9,$E$16,IF($H$17=$D$17,$E$17,$E$18))*S24 -> 0 | V24: =+T24*$H$16 -> 0 | W24: =+U24+V24 -> 0 | Y24: =+D24-M24-S24 -> 0 | Z24: =+E24-N24-T24 -> 0 | AA24: =IF($H$17<9,$E$16,IF($H$17=$D$17,$E$17,$E$18))*Y24 -> 0 | AB24: =+Z24*$H$16 -> 0 | AC24: =+AA24+AB24 -> 0 | AE24: =+D24-M24-S24-Y24 -> 0 | AF24: =+E24-N24-T24-Z24 -> 0 | AG24: =IF($H$17<9,$E$16,IF($H$17=$D$17,$E$17,$E$18))*AE24 -> 0 | AH24: =+AF24*$H$16 -> 0 | AI24: =+AG24+AH24 -> 0
A25: PROFESIONAL | B25: García Atutxa, Igor | C25: =VLOOKUP(B25,'DATOS ASIGNACIÓN'!B:I,4,0) -> 45752839C | D25: =COUNTIFS('LISTADOS TFM'!D:D,Pagos!B25,'LISTADOS TFM'!S:S,"SÍ") -> 0 | E25: =COUNTIF('LISTADOS TFM'!J:L,Pagos!B25) -> 0 | G25: =IF($H$17<9,$E$16,IF($H$17=$D$17,$E$17,$E$18))*D25 -> 0 | H25: =+E25*$H$16 -> 0 | J25: =IF(I25="SÍ",H25*-1,0) -> 0 | K25: =+G25+H25 -> 0 | M25: =+D25 -> 0 | N25: =+E25 -> 0 | O25: =IF($H$17<9,$E$16,IF($H$17=$D$17,$E$17,$E$18))*M25 -> 0 | P25: =+N25*$H$16 -> 0 | Q25: =+O25+P25 -> 0 | S25: =+D25-M25 -> 0 | T25: =+E25-N25 -> 0 | U25: =IF($H$17<9,$E$16,IF($H$17=$D$17,$E$17,$E$18))*S25 -> 0 | V25: =+T25*$H$16 -> 0 | W25: =+U25+V25 -> 0 | Y25: =+D25-M25-S25 -> 0 | Z25: =+E25-N25-T25 -> 0 | AA25: =IF($H$17<9,$E$16,IF($H$17=$D$17,$E$17,$E$18))*Y25 -> 0 | AB25: =+Z25*$H$16 -> 0 | AC25: =+AA25+AB25 -> 0 | AE25: =+D25-M25-S25-Y25 -> 0 | AF25: =+E25-N25-T25-Z25 -> 0 | AG25: =IF($H$17<9,$E$16,IF($H$17=$D$17,$E$17,$E$18))*AE25 -> 0 | AH25: =+AF25*$H$16 -> 0 | AI25: =+AG25+AH25 -> 0
A26: PROFESIONAL | B26: Guijarro Blanco, José María | C26: =VLOOKUP(B26,'DATOS ASIGNACIÓN'!B:I,4,0) -> 21011903T | D26: =COUNTIFS('LISTADOS TFM'!D:D,Pagos!B26,'LISTADOS TFM'!S:S,"SÍ") -> 0 | E26: =COUNTIF('LISTADOS TFM'!J:L,Pagos!B26) -> 0 | G26: =IF($H$17<9,$E$16,IF($H$17=$D$17,$E$17,$E$18))*D26 -> 0 | H26: =+E26*$H$16 -> 0 | J26: =IF(I26="SÍ",H26*-1,0) -> 0 | K26: =+G26+H26 -> 0 | M26: =+D26 -> 0 | N26: =+E26 -> 0 | O26: =IF($H$17<9,$E$16,IF($H$17=$D$17,$E$17,$E$18))*M26 -> 0 | P26: =+N26*$H$16 -> 0 | Q26: =+O26+P26 -> 0 | S26: =+D26-M26 -> 0 | T26: =+E26-N26 -> 0 | U26: =IF($H$17<9,$E$16,IF($H$17=$D$17,$E$17,$E$18))*S26 -> 0 | V26: =+T26*$H$16 -> 0 | W26: =+U26+V26 -> 0 | Y26: =+D26-M26-S26 -> 0 | Z26: =+E26-N26-T26 -> 0 | AA26: =IF($H$17<9,$E$16,IF($H$17=$D$17,$E$17,$E$18))*Y26 -> 0 | AB26: =+Z26*$H$16 -> 0 | AC26: =+AA26+AB26 -> 0 | AE26: =+D26-M26-S26-Y26 -> 0 | AF26: =+E26-N26-T26-Z26 -> 0 | AG26: =IF($H$17<9,$E$16,IF($H$17=$D$17,$E$17,$E$18))*AE26 -> 0 | AH26: =+AF26*$H$16 -> 0 | AI26: =+AG26+AH26 -> 0
A27: PROFESIONAL | B27: Guillén Martín, María de la Paz | C27: =VLOOKUP(B27,'DATOS ASIGNACIÓN'!B:I,4,0) -> 18459003P | D27: =COUNTIFS('LISTADOS TFM'!D:D,Pagos!B27,'LISTADOS TFM'!S:S,"SÍ") -> 0 | E27: =COUNTIF('LISTADOS TFM'!J:L,Pagos!B27) -> 0 | G27: =IF($H$17<9,$E$16,IF($H$17=$D$17,$E$17,$E$18))*D27 -> 0 | H27: =+E27*$H$16 -> 0 | J27: =IF(I27="SÍ",H27*-1,0) -> 0 | K27: =+G27+H27 -> 0 | M27: =+D27 -> 0 | N27: =+E27 -> 0 | O27: =IF($H$17<9,$E$16,IF($H$17=$D$17,$E$17,$E$18))*M27 -> 0 | P27: =+N27*$H$16 -> 0 | Q27: =+O27+P27 -> 0 | S27: =+D27-M27 -> 0 | T27: =+E27-N27 -> 0 | U27: =IF($H$17<9,$E$16,IF($H$17=$D$17,$E$17,$E$18))*S27 -> 0 | V27: =+T27*$H$16 -> 0 | W27: =+U27+V27 -> 0 | Y27: =+D27-M27-S27 -> 0 | Z27: =+E27-N27-T27 -> 0 | AA27: =IF($H$17<9,$E$16,IF($H$17=$D$17,$E$17,$E$18))*Y27 -> 0 | AB27: =+Z27*$H$16 -> 0 | AC27: =+AA27+AB27 -> 0 | AE27: =+D27-M27-S27-Y27 -> 0 | AF27: =+E27-N27-T27-Z27 -> 0 | AG27: =IF($H$17<9,$E$16,IF($H$17=$D$17,$E$17,$E$18))*AE27 -> 0 | AH27: =+AF27*$H$16 -> 0 | AI27: =+AG27+AH27 -> 0
A28: PROFESIONAL | B28: Hernández Hernández, Laura | C28: =VLOOKUP(B28,'DATOS ASIGNACIÓN'!B:I,4,0) -> 07981414T | D28: =COUNTIFS('LISTADOS TFM'!D:D,Pagos!B28,'LISTADOS TFM'!S:S,"SÍ") -> 0 | E28: =COUNTIF('LISTADOS TFM'!J:L,Pagos!B28) -> 0 | G28: =IF($H$17<9,$E$16,IF($H$17=$D$17,$E$17,$E$18))*D28 -> 0 | H28: =+E28*$H$16 -> 0 | J28: =IF(I28="SÍ",H28*-1,0) -> 0 | K28: =+G28+H28 -> 0 | M28: =+D28 -> 0 | N28: =+E28 -> 0 | O28: =IF($H$17<9,$E$16,IF($H$17=$D$17,$E$17,$E$18))*M28 -> 0 | P28: =+N28*$H$16 -> 0 | Q28: =+O28+P28 -> 0 | S28: =+D28-M28 -> 0 | T28: =+E28-N28 -> 0 | U28: =IF($H$17<9,$E$16,IF($H$17=$D$17,$E$17,$E$18))*S28 -> 0 | V28: =+T28*$H$16 -> 0 | W28: =+U28+V28 -> 0 | Y28: =+D28-M28-S28 -> 0 | Z28: =+E28-N28-T28 -> 0 | AA28: =IF($H$17<9,$E$16,IF($H$17=$D$17,$E$17,$E$18))*Y28 -> 0 | AB28: =+Z28*$H$16 -> 0 | AC28: =+AA28+AB28 -> 0 | AE28: =+D28-M28-S28-Y28 -> 0 | AF28: =+E28-N28-T28-Z28 -> 0 | AG28: =IF($H$17<9,$E$16,IF($H$17=$D$17,$E$17,$E$18))*AE28 -> 0 | AH28: =+AF28*$H$16 -> 0 | AI28: =+AG28+AH28 -> 0
A29: PROFESIONAL | B29: López Zaplana, Álvaro | C29: =VLOOKUP(B29,'DATOS ASIGNACIÓN'!B:I,4,0) -> 23300658W | D29: =COUNTIFS('LISTADOS TFM'!D:D,Pagos!B29,'LISTADOS TFM'!S:S,"SÍ") -> 0 | E29: =COUNTIF('LISTADOS TFM'!J:L,Pagos!B29) -> 0 | G29: =IF($H$17<9,$E$16,IF($H$17=$D$17,$E$17,$E$18))*D29 -> 0 | H29: =+E29*$H$16 -> 0 | J29: =IF(I29="SÍ",H29*-1,0) -> 0 | K29: =+G29+H29 -> 0 | M29: =+D29 -> 0 | N29: =+E29 -> 0 | O29: =IF($H$17<9,$E$16,IF($H$17=$D$17,$E$17,$E$18))*M29 -> 0 | P29: =+N29*$H$16 -> 0 | Q29: =+O29+P29 -> 0 | S29: =+D29-M29 -> 0 | T29: =+E29-N29 -> 0 | U29: =IF($H$17<9,$E$16,IF($H$17=$D$17,$E$17,$E$18))*S29 -> 0 | V29: =+T29*$H$16 -> 0 | W29: =+U29+V29 -> 0 | Y29: =+D29-M29-S29 -> 0 | Z29: =+E29-N29-T29 -> 0 | AA29: =IF($H$17<9,$E$16,IF($H$17=$D$17,$E$17,$E$18))*Y29 -> 0 | AB29: =+Z29*$H$16 -> 0 | AC29: =+AA29+AB29 -> 0 | AE29: =+D29-M29-S29-Y29 -> 0 | AF29: =+E29-N29-T29-Z29 -> 0 | AG29: =IF($H$17<9,$E$16,IF($H$17=$D$17,$E$17,$E$18))*AE29 -> 0 | AH29: =+AF29*$H$16 -> 0 | AI29: =+AG29+AH29 -> 0
A30: PROFESIONAL | B30: Marín García, Pablo | C30: =VLOOKUP(B30,'DATOS ASIGNACIÓN'!B:I,4,0) -> 52653545J | D30: =COUNTIFS('LISTADOS TFM'!D:D,Pagos!B30,'LISTADOS TFM'!S:S,"SÍ") -> 0 | E30: =COUNTIF('LISTADOS TFM'!J:L,Pagos!B30) -> 0 | G30: =IF($H$17<9,$E$16,IF($H$17=$D$17,$E$17,$E$18))*D30 -> 0 | H30: =+E30*$H$16 -> 0 | J30: =IF(I30="SÍ",H30*-1,0) -> 0 | K30: =+G30+H30 -> 0 | M30: =+D30 -> 0 | N30: =+E30 -> 0 | O30: =IF($H$17<9,$E$16,IF($H$17=$D$17,$E$17,$E$18))*M30 -> 0 | P30: =+N30*$H$16 -> 0 | Q30: =+O30+P30 -> 0 | S30: =+D30-M30 -> 0 | T30: =+E30-N30 -> 0 | U30: =IF($H$17<9,$E$16,IF($H$17=$D$17,$E$17,$E$18))*S30 -> 0 | V30: =+T30*$H$16 -> 0 | W30: =+U30+V30 -> 0 | Y30: =+D30-M30-S30 -> 0 | Z30: =+E30-N30-T30 -> 0 | AA30: =IF($H$17<9,$E$16,IF($H$17=$D$17,$E$17,$E$18))*Y30 -> 0 | AB30: =+Z30*$H$16 -> 0 | AC30: =+AA30+AB30 -> 0 | AE30: =+D30-M30-S30-Y30 -> 0 | AF30: =+E30-N30-T30-Z30 -> 0 | AG30: =IF($H$17<9,$E$16,IF($H$17=$D$17,$E$17,$E$18))*AE30 -> 0 | AH30: =+AF30*$H$16 -> 0 | AI30: =+AG30+AH30 -> 0
A31: PROFESIONAL | B31: Martínez Montañés, Fernando | C31: =VLOOKUP(B31,'DATOS ASIGNACIÓN'!B:I,4,0) -> 44863903B | D31: =COUNTIFS('LISTADOS TFM'!D:D,Pagos!B31,'LISTADOS TFM'!S:S,"SÍ") -> 0 | E31: =COUNTIF('LISTADOS TFM'!J:L,Pagos!B31) -> 0 | G31: =IF($H$17<9,$E$16,IF($H$17=$D$17,$E$17,$E$18))*D31 -> 0 | H31: =+E31*$H$16 -> 0 | J31: =IF(I31="SÍ",H31*-1,0) -> 0 | K31: =+G31+H31 -> 0 | M31: =+D31 -> 0 | N31: =+E31 -> 0 | O31: =IF($H$17<9,$E$16,IF($H$17=$D$17,$E$17,$E$18))*M31 -> 0 | P31: =+N31*$H$16 -> 0 | Q31: =+O31+P31 -> 0 | S31: =+D31-M31 -> 0 | T31: =+E31-N31 -> 0 | U31: =IF($H$17<9,$E$16,IF($H$17=$D$17,$E$17,$E$18))*S31 -> 0 | V31: =+T31*$H$16 -> 0 | W31: =+U31+V31 -> 0 | Y31: =+D31-M31-S31 -> 0 | Z31: =+E31-N31-T31 -> 0 | AA31: =IF($H$17<9,$E$16,IF($H$17=$D$17,$E$17,$E$18))*Y31 -> 0 | AB31: =+Z31*$H$16 -> 0 | AC31: =+AA31+AB31 -> 0 | AE31: =+D31-M31-S31-Y31 -> 0 | AF31: =+E31-N31-T31-Z31 -> 0 | AG31: =IF($H$17<9,$E$16,IF($H$17=$D$17,$E$17,$E$18))*AE31 -> 0 | AH31: =+AF31*$H$16 -> 0 | AI31: =+AG31+AH31 -> 0
A32: PROFESIONAL | B32: Moldovan Moldovan, Roxana Andreea | C32: =VLOOKUP(B32,'DATOS ASIGNACIÓN'!B:I,4,0) -> 06339169R | D32: =COUNTIFS('LISTADOS TFM'!D:D,Pagos!B32,'LISTADOS TFM'!S:S,"SÍ") -> 0 | E32: =COUNTIF('LISTADOS TFM'!J:L,Pagos!B32) -> 0 | G32: =IF($H$17<9,$E$16,IF($H$17=$D$17,$E$17,$E$18))*D32 -> 0 | H32: =+E32*$H$16 -> 0 | J32: =IF(I32="SÍ",H32*-1,0) -> 0 | K32: =+G32+H32 -> 0 | M32: =+D32 -> 0 | N32: =+E32 -> 0 | O32: =IF($H$17<9,$E$16,IF($H$17=$D$17,$E$17,$E$18))*M32 -> 0 | P32: =+N32*$H$16 -> 0 | Q32: =+O32+P32 -> 0 | S32: =+D32-M32 -> 0 | T32: =+E32-N32 -> 0 | U32: =IF($H$17<9,$E$16,IF($H$17=$D$17,$E$17,$E$18))*S32 -> 0 | V32: =+T32*$H$16 -> 0 | W32: =+U32+V32 -> 0 | Y32: =+D32-M32-S32 -> 0 | Z32: =+E32-N32-T32 -> 0 | AA32: =IF($H$17<9,$E$16,IF($H$17=$D$17,$E$17,$E$18))*Y32 -> 0 | AB32: =+Z32*$H$16 -> 0 | AC32: =+AA32+AB32 -> 0 | AE32: =+D32-M32-S32-Y32 -> 0 | AF32: =+E32-N32-T32-Z32 -> 0 | AG32: =IF($H$17<9,$E$16,IF($H$17=$D$17,$E$17,$E$18))*AE32 -> 0 | AH32: =+AF32*$H$16 -> 0 | AI32: =+AG32+AH32 -> 0
A33: PROFESIONAL | B33: Morante Palacios, Octavio | C33: =VLOOKUP(B33,'DATOS ASIGNACIÓN'!B:I,4,0) -> 44891300S | D33: =COUNTIFS('LISTADOS TFM'!D:D,Pagos!B33,'LISTADOS TFM'!S:S,"SÍ") -> 0 | E33: =COUNTIF('LISTADOS TFM'!J:L,Pagos!B33) -> 0 | G33: =IF($H$17<9,$E$16,IF($H$17=$D$17,$E$17,$E$18))*D33 -> 0 | H33: =+E33*$H$16 -> 0 | J33: =IF(I33="SÍ",H33*-1,0) -> 0 | K33: =+G33+H33 -> 0 | M33: =+D33 -> 0 | N33: =+E33 -> 0 | O33: =IF($H$17<9,$E$16,IF($H$17=$D$17,$E$17,$E$18))*M33 -> 0 | P33: =+N33*$H$16 -> 0 | Q33: =+O33+P33 -> 0 | S33: =+D33-M33 -> 0 | T33: =+E33-N33 -> 0 | U33: =IF($H$17<9,$E$16,IF($H$17=$D$17,$E$17,$E$18))*S33 -> 0 | V33: =+T33*$H$16 -> 0 | W33: =+U33+V33 -> 0 | Y33: =+D33-M33-S33 -> 0 | Z33: =+E33-N33-T33 -> 0 | AA33: =IF($H$17<9,$E$16,IF($H$17=$D$17,$E$17,$E$18))*Y33 -> 0 | AB33: =+Z33*$H$16 -> 0 | AC33: =+AA33+AB33 -> 0 | AE33: =+D33-M33-S33-Y33 -> 0 | AF33: =+E33-N33-T33-Z33 -> 0 | AG33: =IF($H$17<9,$E$16,IF($H$17=$D$17,$E$17,$E$18))*AE33 -> 0 | AH33: =+AF33*$H$16 -> 0 | AI33: =+AG33+AH33 -> 0
A34: PROFESIONAL | B34: Neef, Alexander | C34: =VLOOKUP(B34,'DATOS ASIGNACIÓN'!B:I,4,0) -> X5510546E | D34: =COUNTIFS('LISTADOS TFM'!D:D,Pagos!B34,'LISTADOS TFM'!S:S,"SÍ") -> 0 | E34: =COUNTIF('LISTADOS TFM'!J:L,Pagos!B34) -> 0 | G34: =IF($H$17<9,$E$16,IF($H$17=$D$17,$E$17,$E$18))*D34 -> 0 | H34: =+E34*$H$16 -> 0 | J34: =IF(I34="SÍ",H34*-1,0) -> 0 | K34: =+G34+H34 -> 0 | M34: =+D34 -> 0 | N34: =+E34 -> 0 | O34: =IF($H$17<9,$E$16,IF($H$17=$D$17,$E$17,$E$18))*M34 -> 0 | P34: =+N34*$H$16 -> 0 | Q34: =+O34+P34 -> 0 | S34: =+D34-M34 -> 0 | T34: =+E34-N34 -> 0 | U34: =IF($H$17<9,$E$16,IF($H$17=$D$17,$E$17,$E$18))*S34 -> 0 | V34: =+T34*$H$16 -> 0 | W34: =+U34+V34 -> 0 | Y34: =+D34-M34-S34 -> 0 | Z34: =+E34-N34-T34 -> 0 | AA34: =IF($H$17<9,$E$16,IF($H$17=$D$17,$E$17,$E$18))*Y34 -> 0 | AB34: =+Z34*$H$16 -> 0 | AC34: =+AA34+AB34 -> 0 | AE34: =+D34-M34-S34-Y34 -> 0 | AF34: =+E34-N34-T34-Z34 -> 0 | AG34: =IF($H$17<9,$E$16,IF($H$17=$D$17,$E$17,$E$18))*AE34 -> 0 | AH34: =+AF34*$H$16 -> 0 | AI34: =+AG34+AH34 -> 0
... A41: PROFESIONAL | B41: Zúñiga Trejos, Sheila | C41: =VLOOKUP(B41,'DATOS ASIGNACIÓN'!B:I,4,0) -> 70874038K | D41: =COUNTIFS('LISTADOS TFM'!D:D,Pagos!B41,'LISTADOS TFM'!S:S,"SÍ") -> 0 | E41: =COUNTIF('LISTADOS TFM'!J:L,Pagos!B41) -> 0 | G41: =IF($H$17<9,$E$16,IF($H$17=$D$17,$E$17,$E$18))*D41 -> 0 | H41: =+E41*$H$16 -> 0 | J41: =IF(I41="SÍ",H41*-1,0) -> 0 | K41: =+G41+H41 -> 0 | M41: =+D41 -> 0 | N41: =+E41 -> 0 | O41: =IF($H$17<9,$E$16,IF($H$17=$D$17,$E$17,$E$18))*M41 -> 0 | P41: =+N41*$H$16 -> 0 | Q41: =+O41+P41 -> 0 | S41: =+D41-M41 -> 0 | T41: =+E41-N41 -> 0 | U41: =IF($H$17<9,$E$16,IF($H$17=$D$17,$E$17,$E$18))*S41 -> 0 | V41: =+T41*$H$16 -> 0 | W41: =+U41+V41 -> 0 | Y41: =+D41-M41-S41 -> 0 | Z41: =+E41-N41-T41 -> 0 | AA41: =IF($H$17<9,$E$16,IF($H$17=$D$17,$E$17,$E$18))*Y41 -> 0 | AB41: =+Z41*$H$16 -> 0 | AC41: =+AA41+AB41 -> 0 | AE41: =+D41-M41-S41-Y41 -> 0 | AF41: =+E41-N41-T41-Z41 -> 0 | AG41: =IF($H$17<9,$E$16,IF($H$17=$D$17,$E$17,$E$18))*AE41 -> 0 | AH41: =+AF41*$H$16 -> 0 | AI41: =+AG41+AH41 -> 0
A42: PROFESIONAL | C42: =VLOOKUP(B42,'DATOS ASIGNACIÓN'!B:I,4,0) -> #N/A | D42: =COUNTIFS('LISTADOS TFM'!D:D,Pagos!B42,'LISTADOS TFM'!S:S,"SÍ") -> 0 | E42: =COUNTIF('LISTADOS TFM'!J:L,Pagos!B42) -> 0 | G42: =IF($H$17<9,$E$16,IF($H$17=$D$17,$E$17,$E$18))*D42 -> 0 | H42: =+E42*$H$16 -> 0 | J42: =IF(I42="SÍ",H42*-1,0) -> 0 | K42: =+G42+H42 -> 0 | M42: =+D42 -> 0 | N42: =+E42 -> 0 | O42: =IF($H$17<9,$E$16,IF($H$17=$D$17,$E$17,$E$18))*M42 -> 0 | P42: =+N42*$H$16 -> 0 | Q42: =+O42+P42 -> 0 | S42: =+D42-M42 -> 0 | T42: =+E42-N42 -> 0 | U42: =IF($H$17<9,$E$16,IF($H$17=$D$17,$E$17,$E$18))*S42 -> 0 | V42: =+T42*$H$16 -> 0 | W42: =+U42+V42 -> 0 | Y42: =+D42-M42-S42 -> 0 | Z42: =+E42-N42-T42 -> 0 | AA42: =IF($H$17<9,$E$16,IF($H$17=$D$17,$E$17,$E$18))*Y42 -> 0 | AB42: =+Z42*$H$16 -> 0 | AC42: =+AA42+AB42 -> 0 | AE42: =+D42-M42-S42-Y42 -> 0 | AF42: =+E42-N42-T42-Z42 -> 0 | AG42: =IF($H$17<9,$E$16,IF($H$17=$D$17,$E$17,$E$18))*AE42 -> 0 | AH42: =+AF42*$H$16 -> 0 | AI42: =+AG42+AH42 -> 0
A43: PROFESIONAL | C43: =VLOOKUP(B43,'DATOS ASIGNACIÓN'!B:I,4,0) -> #N/A | D43: =COUNTIFS('LISTADOS TFM'!D:D,Pagos!B43,'LISTADOS TFM'!S:S,"SÍ") -> 0 | E43: =COUNTIF('LISTADOS TFM'!J:L,Pagos!B43) -> 0 | G43: =IF($H$17<9,$E$16,IF($H$17=$D$17,$E$17,$E$18))*D43 -> 0 | H43: =+E43*$H$16 -> 0 | J43: =IF(I43="SÍ",H43*-1,0) -> 0 | K43: =+G43+H43 -> 0 | M43: =+D43 -> 0 | N43: =+E43 -> 0 | O43: =IF($H$17<9,$E$16,IF($H$17=$D$17,$E$17,$E$18))*M43 -> 0 | P43: =+N43*$H$16 -> 0 | Q43: =+O43+P43 -> 0 | S43: =+D43-M43 -> 0 | T43: =+E43-N43 -> 0 | U43: =IF($H$17<9,$E$16,IF($H$17=$D$17,$E$17,$E$18))*S43 -> 0 | V43: =+T43*$H$16 -> 0 | W43: =+U43+V43 -> 0 | Y43: =+D43-M43-S43 -> 0 | Z43: =+E43-N43-T43 -> 0 | AA43: =IF($H$17<9,$E$16,IF($H$17=$D$17,$E$17,$E$18))*Y43 -> 0 | AB43: =+Z43*$H$16 -> 0 | AC43: =+AA43+AB43 -> 0 | AE43: =+D43-M43-S43-Y43 -> 0 | AF43: =+E43-N43-T43-Z43 -> 0 | AG43: =IF($H$17<9,$E$16,IF($H$17=$D$17,$E$17,$E$18))*AE43 -> 0 | AH43: =+AF43*$H$16 -> 0 | AI43: =+AG43+AH43 -> 0
